[2024-01-04T20:53:27.339+0000] {taskinstance.py:1957} INFO - Dependencies all met for dep_context=non-requeueable deps ti=<TaskInstance: write_dag_dataset.update_file scheduled__2024-01-03T00:00:00+00:00 [queued]>
[2024-01-04T20:53:27.360+0000] {taskinstance.py:1957} INFO - Dependencies all met for dep_context=requeueable deps ti=<TaskInstance: write_dag_dataset.update_file scheduled__2024-01-03T00:00:00+00:00 [queued]>
[2024-01-04T20:53:27.362+0000] {taskinstance.py:2171} INFO - Starting attempt 1 of 1
[2024-01-04T20:53:27.398+0000] {taskinstance.py:2192} INFO - Executing <Task(_PythonDecoratedOperator): update_file> on 2024-01-03 00:00:00+00:00
[2024-01-04T20:53:27.418+0000] {standard_task_runner.py:60} INFO - Started process 969 to run task
[2024-01-04T20:53:27.530+0000] {standard_task_runner.py:87} INFO - Running: ['***', 'tasks', 'run', 'write_dag_dataset', 'update_file', 'scheduled__2024-01-03T00:00:00+00:00', '--job-id', '20', '--raw', '--subdir', 'DAGS_FOLDER/dataset_dag.py', '--cfg-path', '/tmp/tmp3k102zlu']
[2024-01-04T20:53:27.613+0000] {standard_task_runner.py:88} INFO - Job 20: Subtask update_file
[2024-01-04T20:53:28.262+0000] {task_command.py:423} INFO - Running <TaskInstance: write_dag_dataset.update_file scheduled__2024-01-03T00:00:00+00:00 [running]> on host 75bffd784e7d
[2024-01-04T20:53:28.703+0000] {taskinstance.py:2481} INFO - Exporting env vars: AIRFLOW_CTX_DAG_OWNER='***' AIRFLOW_CTX_DAG_ID='write_dag_dataset' AIRFLOW_CTX_TASK_ID='update_file' AIRFLOW_CTX_EXECUTION_DATE='2024-01-03T00:00:00+00:00' AIRFLOW_CTX_TRY_NUMBER='1' AIRFLOW_CTX_DAG_RUN_ID='scheduled__2024-01-03T00:00:00+00:00'
[2024-01-04T20:53:28.707+0000] {taskinstance.py:2699} ERROR - Task failed with exception
Traceback (most recent call last):
  File "/home/airflow/.local/lib/python3.8/site-packages/airflow/models/taskinstance.py", line 433, in _execute_task
    result = execute_callable(context=context, **execute_callable_kwargs)
  File "/home/airflow/.local/lib/python3.8/site-packages/airflow/decorators/base.py", line 242, in execute
    return_value = super().execute(context)
  File "/home/airflow/.local/lib/python3.8/site-packages/airflow/operators/python.py", line 199, in execute
    return_value = self.execute_callable()
  File "/home/airflow/.local/lib/python3.8/site-packages/airflow/operators/python.py", line 216, in execute_callable
    return self.python_callable(*self.op_args, **self.op_kwargs)
  File "/opt/airflow/dags/dataset_dag.py", line 17, in update_file
    with open(my_file.uri, "a+") as f:  # this opens a file speciifc by the uri in append mode ("a+")
FileNotFoundError: [Errno 2] No such file or directory: 'tmp/my_file.txt'
[2024-01-04T20:53:28.735+0000] {taskinstance.py:1138} INFO - Marking task as FAILED. dag_id=write_dag_dataset, task_id=update_file, execution_date=20240103T000000, start_date=20240104T205327, end_date=20240104T205328
[2024-01-04T20:53:28.765+0000] {standard_task_runner.py:107} ERROR - Failed to execute job 20 for task update_file ([Errno 2] No such file or directory: 'tmp/my_file.txt'; 969)
[2024-01-04T20:53:28.811+0000] {local_task_job_runner.py:234} INFO - Task exited with return code 1
[2024-01-04T20:53:28.849+0000] {taskinstance.py:3281} INFO - 0 downstream tasks scheduled from follow-on schedule check
