[2024-01-04T20:51:02.303+0000] {processor.py:161} INFO - Started process (PID=6642) to work on /opt/airflow/dags/read_dataset_dag.py
[2024-01-04T20:51:02.313+0000] {processor.py:830} INFO - Processing file /opt/airflow/dags/read_dataset_dag.py for tasks to queue
[2024-01-04T20:51:02.316+0000] {logging_mixin.py:188} INFO - [2024-01-04T20:51:02.315+0000] {dagbag.py:538} INFO - Filling up the DagBag from /opt/airflow/dags/read_dataset_dag.py
[2024-01-04T20:51:03.154+0000] {logging_mixin.py:188} INFO - [2024-01-04T20:51:03.057+0000] {dagbag.py:348} ERROR - Failed to import: /opt/airflow/dags/read_dataset_dag.py
Traceback (most recent call last):
  File "/home/airflow/.local/lib/python3.8/site-packages/airflow/models/dagbag.py", line 344, in parse
    loader.exec_module(new_module)
  File "<frozen importlib._bootstrap_external>", line 843, in exec_module
  File "<frozen importlib._bootstrap>", line 219, in _call_with_frames_removed
  File "/opt/airflow/dags/read_dataset_dag.py", line 7, in <module>
    with DAG(
  File "/home/airflow/.local/lib/python3.8/site-packages/airflow/models/dag.py", line 600, in __init__
    self.timetable = create_timetable(schedule_interval, self.timezone)
  File "/home/airflow/.local/lib/python3.8/site-packages/airflow/models/dag.py", line 230, in create_timetable
    raise ValueError(f"{interval!r} is not a valid interval.")
ValueError: [Dataset(uri='tmp/my_file.txt', extra=None)] is not a valid interval.
[2024-01-04T20:51:03.158+0000] {processor.py:842} WARNING - No viable dags retrieved from /opt/airflow/dags/read_dataset_dag.py
[2024-01-04T20:51:03.539+0000] {processor.py:183} INFO - Processing /opt/airflow/dags/read_dataset_dag.py took 1.253 seconds
[2024-01-04T20:51:33.749+0000] {processor.py:161} INFO - Started process (PID=6706) to work on /opt/airflow/dags/read_dataset_dag.py
[2024-01-04T20:51:33.751+0000] {processor.py:830} INFO - Processing file /opt/airflow/dags/read_dataset_dag.py for tasks to queue
[2024-01-04T20:51:33.752+0000] {logging_mixin.py:188} INFO - [2024-01-04T20:51:33.752+0000] {dagbag.py:538} INFO - Filling up the DagBag from /opt/airflow/dags/read_dataset_dag.py
[2024-01-04T20:51:33.780+0000] {logging_mixin.py:188} INFO - [2024-01-04T20:51:33.775+0000] {dagbag.py:348} ERROR - Failed to import: /opt/airflow/dags/read_dataset_dag.py
Traceback (most recent call last):
  File "/home/airflow/.local/lib/python3.8/site-packages/airflow/models/dagbag.py", line 344, in parse
    loader.exec_module(new_module)
  File "<frozen importlib._bootstrap_external>", line 843, in exec_module
  File "<frozen importlib._bootstrap>", line 219, in _call_with_frames_removed
  File "/opt/airflow/dags/read_dataset_dag.py", line 7, in <module>
    with DAG(
  File "/home/airflow/.local/lib/python3.8/site-packages/airflow/models/dag.py", line 600, in __init__
    self.timetable = create_timetable(schedule_interval, self.timezone)
  File "/home/airflow/.local/lib/python3.8/site-packages/airflow/models/dag.py", line 230, in create_timetable
    raise ValueError(f"{interval!r} is not a valid interval.")
ValueError: [Dataset(uri='tmp/my_file.txt', extra=None)] is not a valid interval.
[2024-01-04T20:51:33.780+0000] {processor.py:842} WARNING - No viable dags retrieved from /opt/airflow/dags/read_dataset_dag.py
[2024-01-04T20:51:33.806+0000] {processor.py:183} INFO - Processing /opt/airflow/dags/read_dataset_dag.py took 0.060 seconds
[2024-01-04T20:52:04.281+0000] {processor.py:161} INFO - Started process (PID=6765) to work on /opt/airflow/dags/read_dataset_dag.py
[2024-01-04T20:52:04.284+0000] {processor.py:830} INFO - Processing file /opt/airflow/dags/read_dataset_dag.py for tasks to queue
[2024-01-04T20:52:04.286+0000] {logging_mixin.py:188} INFO - [2024-01-04T20:52:04.285+0000] {dagbag.py:538} INFO - Filling up the DagBag from /opt/airflow/dags/read_dataset_dag.py
[2024-01-04T20:52:04.329+0000] {logging_mixin.py:188} INFO - [2024-01-04T20:52:04.320+0000] {dagbag.py:348} ERROR - Failed to import: /opt/airflow/dags/read_dataset_dag.py
Traceback (most recent call last):
  File "/home/airflow/.local/lib/python3.8/site-packages/airflow/models/dagbag.py", line 344, in parse
    loader.exec_module(new_module)
  File "<frozen importlib._bootstrap_external>", line 843, in exec_module
  File "<frozen importlib._bootstrap>", line 219, in _call_with_frames_removed
  File "/opt/airflow/dags/read_dataset_dag.py", line 7, in <module>
    with DAG(
  File "/home/airflow/.local/lib/python3.8/site-packages/airflow/models/dag.py", line 600, in __init__
    self.timetable = create_timetable(schedule_interval, self.timezone)
  File "/home/airflow/.local/lib/python3.8/site-packages/airflow/models/dag.py", line 230, in create_timetable
    raise ValueError(f"{interval!r} is not a valid interval.")
ValueError: [Dataset(uri='tmp/my_file.txt', extra=None)] is not a valid interval.
[2024-01-04T20:52:04.331+0000] {processor.py:842} WARNING - No viable dags retrieved from /opt/airflow/dags/read_dataset_dag.py
[2024-01-04T20:52:04.377+0000] {processor.py:183} INFO - Processing /opt/airflow/dags/read_dataset_dag.py took 0.110 seconds
[2024-01-04T20:52:34.939+0000] {processor.py:161} INFO - Started process (PID=6824) to work on /opt/airflow/dags/read_dataset_dag.py
[2024-01-04T20:52:34.941+0000] {processor.py:830} INFO - Processing file /opt/airflow/dags/read_dataset_dag.py for tasks to queue
[2024-01-04T20:52:34.942+0000] {logging_mixin.py:188} INFO - [2024-01-04T20:52:34.942+0000] {dagbag.py:538} INFO - Filling up the DagBag from /opt/airflow/dags/read_dataset_dag.py
[2024-01-04T20:52:34.978+0000] {logging_mixin.py:188} INFO - [2024-01-04T20:52:34.972+0000] {dagbag.py:348} ERROR - Failed to import: /opt/airflow/dags/read_dataset_dag.py
Traceback (most recent call last):
  File "/home/airflow/.local/lib/python3.8/site-packages/airflow/models/dagbag.py", line 344, in parse
    loader.exec_module(new_module)
  File "<frozen importlib._bootstrap_external>", line 843, in exec_module
  File "<frozen importlib._bootstrap>", line 219, in _call_with_frames_removed
  File "/opt/airflow/dags/read_dataset_dag.py", line 7, in <module>
    with DAG(
  File "/home/airflow/.local/lib/python3.8/site-packages/airflow/models/dag.py", line 600, in __init__
    self.timetable = create_timetable(schedule_interval, self.timezone)
  File "/home/airflow/.local/lib/python3.8/site-packages/airflow/models/dag.py", line 230, in create_timetable
    raise ValueError(f"{interval!r} is not a valid interval.")
ValueError: [Dataset(uri='tmp/my_file.txt', extra=None)] is not a valid interval.
[2024-01-04T20:52:34.978+0000] {processor.py:842} WARNING - No viable dags retrieved from /opt/airflow/dags/read_dataset_dag.py
[2024-01-04T20:52:35.017+0000] {processor.py:183} INFO - Processing /opt/airflow/dags/read_dataset_dag.py took 0.082 seconds
[2024-01-04T20:52:50.090+0000] {processor.py:161} INFO - Started process (PID=6843) to work on /opt/airflow/dags/read_dataset_dag.py
[2024-01-04T20:52:50.094+0000] {processor.py:830} INFO - Processing file /opt/airflow/dags/read_dataset_dag.py for tasks to queue
[2024-01-04T20:52:50.096+0000] {logging_mixin.py:188} INFO - [2024-01-04T20:52:50.096+0000] {dagbag.py:538} INFO - Filling up the DagBag from /opt/airflow/dags/read_dataset_dag.py
[2024-01-04T20:52:50.157+0000] {logging_mixin.py:188} INFO - [2024-01-04T20:52:50.147+0000] {dagbag.py:348} ERROR - Failed to import: /opt/airflow/dags/read_dataset_dag.py
Traceback (most recent call last):
  File "/home/airflow/.local/lib/python3.8/site-packages/airflow/models/dagbag.py", line 344, in parse
    loader.exec_module(new_module)
  File "<frozen importlib._bootstrap_external>", line 843, in exec_module
  File "<frozen importlib._bootstrap>", line 219, in _call_with_frames_removed
  File "/opt/airflow/dags/read_dataset_dag.py", line 7, in <module>
    with DAG(
  File "/home/airflow/.local/lib/python3.8/site-packages/airflow/models/dag.py", line 600, in __init__
    self.timetable = create_timetable(schedule_interval, self.timezone)
  File "/home/airflow/.local/lib/python3.8/site-packages/airflow/models/dag.py", line 230, in create_timetable
    raise ValueError(f"{interval!r} is not a valid interval.")
ValueError: [Dataset(uri='tmp/my_file.txt', extra=None)] is not a valid interval.
[2024-01-04T20:52:50.158+0000] {processor.py:842} WARNING - No viable dags retrieved from /opt/airflow/dags/read_dataset_dag.py
[2024-01-04T20:52:50.202+0000] {processor.py:183} INFO - Processing /opt/airflow/dags/read_dataset_dag.py took 0.121 seconds
[2024-01-04T20:53:20.605+0000] {processor.py:161} INFO - Started process (PID=6902) to work on /opt/airflow/dags/read_dataset_dag.py
[2024-01-04T20:53:20.610+0000] {processor.py:830} INFO - Processing file /opt/airflow/dags/read_dataset_dag.py for tasks to queue
[2024-01-04T20:53:20.612+0000] {logging_mixin.py:188} INFO - [2024-01-04T20:53:20.611+0000] {dagbag.py:538} INFO - Filling up the DagBag from /opt/airflow/dags/read_dataset_dag.py
[2024-01-04T20:53:20.683+0000] {logging_mixin.py:188} INFO - [2024-01-04T20:53:20.670+0000] {dagbag.py:348} ERROR - Failed to import: /opt/airflow/dags/read_dataset_dag.py
Traceback (most recent call last):
  File "/home/airflow/.local/lib/python3.8/site-packages/airflow/models/dagbag.py", line 344, in parse
    loader.exec_module(new_module)
  File "<frozen importlib._bootstrap_external>", line 843, in exec_module
  File "<frozen importlib._bootstrap>", line 219, in _call_with_frames_removed
  File "/opt/airflow/dags/read_dataset_dag.py", line 7, in <module>
    with DAG(
  File "/home/airflow/.local/lib/python3.8/site-packages/airflow/models/dag.py", line 600, in __init__
    self.timetable = create_timetable(schedule_interval, self.timezone)
  File "/home/airflow/.local/lib/python3.8/site-packages/airflow/models/dag.py", line 230, in create_timetable
    raise ValueError(f"{interval!r} is not a valid interval.")
ValueError: [Dataset(uri='tmp/my_file.txt', extra=None)] is not a valid interval.
[2024-01-04T20:53:20.684+0000] {processor.py:842} WARNING - No viable dags retrieved from /opt/airflow/dags/read_dataset_dag.py
[2024-01-04T20:53:20.801+0000] {processor.py:183} INFO - Processing /opt/airflow/dags/read_dataset_dag.py took 0.200 seconds
[2024-01-04T20:53:51.560+0000] {processor.py:161} INFO - Started process (PID=6961) to work on /opt/airflow/dags/read_dataset_dag.py
[2024-01-04T20:53:51.562+0000] {processor.py:830} INFO - Processing file /opt/airflow/dags/read_dataset_dag.py for tasks to queue
[2024-01-04T20:53:51.565+0000] {logging_mixin.py:188} INFO - [2024-01-04T20:53:51.564+0000] {dagbag.py:538} INFO - Filling up the DagBag from /opt/airflow/dags/read_dataset_dag.py
[2024-01-04T20:53:51.610+0000] {logging_mixin.py:188} INFO - [2024-01-04T20:53:51.593+0000] {dagbag.py:348} ERROR - Failed to import: /opt/airflow/dags/read_dataset_dag.py
Traceback (most recent call last):
  File "/home/airflow/.local/lib/python3.8/site-packages/airflow/models/dagbag.py", line 344, in parse
    loader.exec_module(new_module)
  File "<frozen importlib._bootstrap_external>", line 843, in exec_module
  File "<frozen importlib._bootstrap>", line 219, in _call_with_frames_removed
  File "/opt/airflow/dags/read_dataset_dag.py", line 7, in <module>
    with DAG(
  File "/home/airflow/.local/lib/python3.8/site-packages/airflow/models/dag.py", line 600, in __init__
    self.timetable = create_timetable(schedule_interval, self.timezone)
  File "/home/airflow/.local/lib/python3.8/site-packages/airflow/models/dag.py", line 230, in create_timetable
    raise ValueError(f"{interval!r} is not a valid interval.")
ValueError: [Dataset(uri='tmp/my_file.txt', extra=None)] is not a valid interval.
[2024-01-04T20:53:51.611+0000] {processor.py:842} WARNING - No viable dags retrieved from /opt/airflow/dags/read_dataset_dag.py
[2024-01-04T20:53:51.665+0000] {processor.py:183} INFO - Processing /opt/airflow/dags/read_dataset_dag.py took 0.110 seconds
[2024-01-04T20:54:22.294+0000] {processor.py:161} INFO - Started process (PID=7020) to work on /opt/airflow/dags/read_dataset_dag.py
[2024-01-04T20:54:22.296+0000] {processor.py:830} INFO - Processing file /opt/airflow/dags/read_dataset_dag.py for tasks to queue
[2024-01-04T20:54:22.298+0000] {logging_mixin.py:188} INFO - [2024-01-04T20:54:22.298+0000] {dagbag.py:538} INFO - Filling up the DagBag from /opt/airflow/dags/read_dataset_dag.py
[2024-01-04T20:54:22.336+0000] {logging_mixin.py:188} INFO - [2024-01-04T20:54:22.328+0000] {dagbag.py:348} ERROR - Failed to import: /opt/airflow/dags/read_dataset_dag.py
Traceback (most recent call last):
  File "/home/airflow/.local/lib/python3.8/site-packages/airflow/models/dagbag.py", line 344, in parse
    loader.exec_module(new_module)
  File "<frozen importlib._bootstrap_external>", line 843, in exec_module
  File "<frozen importlib._bootstrap>", line 219, in _call_with_frames_removed
  File "/opt/airflow/dags/read_dataset_dag.py", line 7, in <module>
    with DAG(
  File "/home/airflow/.local/lib/python3.8/site-packages/airflow/models/dag.py", line 600, in __init__
    self.timetable = create_timetable(schedule_interval, self.timezone)
  File "/home/airflow/.local/lib/python3.8/site-packages/airflow/models/dag.py", line 230, in create_timetable
    raise ValueError(f"{interval!r} is not a valid interval.")
ValueError: [Dataset(uri='tmp/my_file.txt', extra=None)] is not a valid interval.
[2024-01-04T20:54:22.337+0000] {processor.py:842} WARNING - No viable dags retrieved from /opt/airflow/dags/read_dataset_dag.py
[2024-01-04T20:54:22.362+0000] {processor.py:183} INFO - Processing /opt/airflow/dags/read_dataset_dag.py took 0.074 seconds
[2024-01-04T20:54:43.362+0000] {processor.py:161} INFO - Started process (PID=7065) to work on /opt/airflow/dags/read_dataset_dag.py
[2024-01-04T20:54:43.364+0000] {processor.py:830} INFO - Processing file /opt/airflow/dags/read_dataset_dag.py for tasks to queue
[2024-01-04T20:54:43.368+0000] {logging_mixin.py:188} INFO - [2024-01-04T20:54:43.367+0000] {dagbag.py:538} INFO - Filling up the DagBag from /opt/airflow/dags/read_dataset_dag.py
[2024-01-04T20:54:43.439+0000] {logging_mixin.py:188} INFO - [2024-01-04T20:54:43.426+0000] {dagbag.py:348} ERROR - Failed to import: /opt/airflow/dags/read_dataset_dag.py
Traceback (most recent call last):
  File "/home/airflow/.local/lib/python3.8/site-packages/airflow/models/dagbag.py", line 344, in parse
    loader.exec_module(new_module)
  File "<frozen importlib._bootstrap_external>", line 843, in exec_module
  File "<frozen importlib._bootstrap>", line 219, in _call_with_frames_removed
  File "/opt/airflow/dags/read_dataset_dag.py", line 7, in <module>
    with DAG(
  File "/home/airflow/.local/lib/python3.8/site-packages/airflow/models/dag.py", line 600, in __init__
    self.timetable = create_timetable(schedule_interval, self.timezone)
  File "/home/airflow/.local/lib/python3.8/site-packages/airflow/models/dag.py", line 230, in create_timetable
    raise ValueError(f"{interval!r} is not a valid interval.")
ValueError: [Dataset(uri='tmp/my_file.txt', extra=None)] is not a valid interval.
[2024-01-04T20:54:43.440+0000] {processor.py:842} WARNING - No viable dags retrieved from /opt/airflow/dags/read_dataset_dag.py
[2024-01-04T20:54:43.537+0000] {processor.py:183} INFO - Processing /opt/airflow/dags/read_dataset_dag.py took 0.181 seconds
[2024-01-04T20:55:13.839+0000] {processor.py:161} INFO - Started process (PID=7124) to work on /opt/airflow/dags/read_dataset_dag.py
[2024-01-04T20:55:13.841+0000] {processor.py:830} INFO - Processing file /opt/airflow/dags/read_dataset_dag.py for tasks to queue
[2024-01-04T20:55:13.843+0000] {logging_mixin.py:188} INFO - [2024-01-04T20:55:13.842+0000] {dagbag.py:538} INFO - Filling up the DagBag from /opt/airflow/dags/read_dataset_dag.py
[2024-01-04T20:55:13.876+0000] {logging_mixin.py:188} INFO - [2024-01-04T20:55:13.867+0000] {dagbag.py:348} ERROR - Failed to import: /opt/airflow/dags/read_dataset_dag.py
Traceback (most recent call last):
  File "/home/airflow/.local/lib/python3.8/site-packages/airflow/models/dagbag.py", line 344, in parse
    loader.exec_module(new_module)
  File "<frozen importlib._bootstrap_external>", line 843, in exec_module
  File "<frozen importlib._bootstrap>", line 219, in _call_with_frames_removed
  File "/opt/airflow/dags/read_dataset_dag.py", line 7, in <module>
    with DAG(
  File "/home/airflow/.local/lib/python3.8/site-packages/airflow/models/dag.py", line 600, in __init__
    self.timetable = create_timetable(schedule_interval, self.timezone)
  File "/home/airflow/.local/lib/python3.8/site-packages/airflow/models/dag.py", line 230, in create_timetable
    raise ValueError(f"{interval!r} is not a valid interval.")
ValueError: [Dataset(uri='tmp/my_file.txt', extra=None)] is not a valid interval.
[2024-01-04T20:55:13.877+0000] {processor.py:842} WARNING - No viable dags retrieved from /opt/airflow/dags/read_dataset_dag.py
[2024-01-04T20:55:13.915+0000] {processor.py:183} INFO - Processing /opt/airflow/dags/read_dataset_dag.py took 0.080 seconds
[2024-01-04T20:55:55.830+0000] {processor.py:161} INFO - Started process (PID=7180) to work on /opt/airflow/dags/read_dataset_dag.py
[2024-01-04T20:55:55.918+0000] {processor.py:830} INFO - Processing file /opt/airflow/dags/read_dataset_dag.py for tasks to queue
[2024-01-04T20:55:55.922+0000] {logging_mixin.py:188} INFO - [2024-01-04T20:55:55.920+0000] {dagbag.py:538} INFO - Filling up the DagBag from /opt/airflow/dags/read_dataset_dag.py
[2024-01-04T20:55:56.256+0000] {logging_mixin.py:188} INFO - [2024-01-04T20:55:55.964+0000] {dagbag.py:348} ERROR - Failed to import: /opt/airflow/dags/read_dataset_dag.py
Traceback (most recent call last):
  File "/home/airflow/.local/lib/python3.8/site-packages/airflow/models/dagbag.py", line 344, in parse
    loader.exec_module(new_module)
  File "<frozen importlib._bootstrap_external>", line 843, in exec_module
  File "<frozen importlib._bootstrap>", line 219, in _call_with_frames_removed
  File "/opt/airflow/dags/read_dataset_dag.py", line 7, in <module>
    with DAG(
  File "/home/airflow/.local/lib/python3.8/site-packages/airflow/models/dag.py", line 600, in __init__
    self.timetable = create_timetable(schedule_interval, self.timezone)
  File "/home/airflow/.local/lib/python3.8/site-packages/airflow/models/dag.py", line 230, in create_timetable
    raise ValueError(f"{interval!r} is not a valid interval.")
ValueError: [Dataset(uri='tmp/my_file.txt', extra=None)] is not a valid interval.
[2024-01-04T20:55:56.257+0000] {processor.py:842} WARNING - No viable dags retrieved from /opt/airflow/dags/read_dataset_dag.py
[2024-01-04T20:55:56.421+0000] {processor.py:183} INFO - Processing /opt/airflow/dags/read_dataset_dag.py took 0.595 seconds
[2024-01-04T20:56:26.525+0000] {processor.py:161} INFO - Started process (PID=7225) to work on /opt/airflow/dags/read_dataset_dag.py
[2024-01-04T20:56:26.528+0000] {processor.py:830} INFO - Processing file /opt/airflow/dags/read_dataset_dag.py for tasks to queue
[2024-01-04T20:56:26.531+0000] {logging_mixin.py:188} INFO - [2024-01-04T20:56:26.530+0000] {dagbag.py:538} INFO - Filling up the DagBag from /opt/airflow/dags/read_dataset_dag.py
[2024-01-04T20:56:26.574+0000] {logging_mixin.py:188} INFO - [2024-01-04T20:56:26.563+0000] {dagbag.py:348} ERROR - Failed to import: /opt/airflow/dags/read_dataset_dag.py
Traceback (most recent call last):
  File "/home/airflow/.local/lib/python3.8/site-packages/airflow/models/dagbag.py", line 344, in parse
    loader.exec_module(new_module)
  File "<frozen importlib._bootstrap_external>", line 843, in exec_module
  File "<frozen importlib._bootstrap>", line 219, in _call_with_frames_removed
  File "/opt/airflow/dags/read_dataset_dag.py", line 7, in <module>
    with DAG(
  File "/home/airflow/.local/lib/python3.8/site-packages/airflow/models/dag.py", line 600, in __init__
    self.timetable = create_timetable(schedule_interval, self.timezone)
  File "/home/airflow/.local/lib/python3.8/site-packages/airflow/models/dag.py", line 230, in create_timetable
    raise ValueError(f"{interval!r} is not a valid interval.")
ValueError: [Dataset(uri='tmp/my_file.txt', extra=None)] is not a valid interval.
[2024-01-04T20:56:26.576+0000] {processor.py:842} WARNING - No viable dags retrieved from /opt/airflow/dags/read_dataset_dag.py
[2024-01-04T20:56:26.630+0000] {processor.py:183} INFO - Processing /opt/airflow/dags/read_dataset_dag.py took 0.113 seconds
[2024-01-04T20:56:57.236+0000] {processor.py:161} INFO - Started process (PID=7281) to work on /opt/airflow/dags/read_dataset_dag.py
[2024-01-04T20:56:57.251+0000] {processor.py:830} INFO - Processing file /opt/airflow/dags/read_dataset_dag.py for tasks to queue
[2024-01-04T20:56:57.252+0000] {logging_mixin.py:188} INFO - [2024-01-04T20:56:57.252+0000] {dagbag.py:538} INFO - Filling up the DagBag from /opt/airflow/dags/read_dataset_dag.py
[2024-01-04T20:56:57.450+0000] {logging_mixin.py:188} INFO - [2024-01-04T20:56:57.370+0000] {dagbag.py:348} ERROR - Failed to import: /opt/airflow/dags/read_dataset_dag.py
Traceback (most recent call last):
  File "/home/airflow/.local/lib/python3.8/site-packages/airflow/models/dagbag.py", line 344, in parse
    loader.exec_module(new_module)
  File "<frozen importlib._bootstrap_external>", line 843, in exec_module
  File "<frozen importlib._bootstrap>", line 219, in _call_with_frames_removed
  File "/opt/airflow/dags/read_dataset_dag.py", line 7, in <module>
    with DAG(
  File "/home/airflow/.local/lib/python3.8/site-packages/airflow/models/dag.py", line 600, in __init__
    self.timetable = create_timetable(schedule_interval, self.timezone)
  File "/home/airflow/.local/lib/python3.8/site-packages/airflow/models/dag.py", line 230, in create_timetable
    raise ValueError(f"{interval!r} is not a valid interval.")
ValueError: [Dataset(uri='tmp/my_file.txt', extra=None)] is not a valid interval.
[2024-01-04T20:56:57.452+0000] {processor.py:842} WARNING - No viable dags retrieved from /opt/airflow/dags/read_dataset_dag.py
[2024-01-04T20:56:57.852+0000] {processor.py:183} INFO - Processing /opt/airflow/dags/read_dataset_dag.py took 0.620 seconds
[2024-01-04T20:57:28.716+0000] {processor.py:161} INFO - Started process (PID=7339) to work on /opt/airflow/dags/read_dataset_dag.py
[2024-01-04T20:57:28.717+0000] {processor.py:830} INFO - Processing file /opt/airflow/dags/read_dataset_dag.py for tasks to queue
[2024-01-04T20:57:28.719+0000] {logging_mixin.py:188} INFO - [2024-01-04T20:57:28.718+0000] {dagbag.py:538} INFO - Filling up the DagBag from /opt/airflow/dags/read_dataset_dag.py
[2024-01-04T20:57:28.747+0000] {logging_mixin.py:188} INFO - [2024-01-04T20:57:28.739+0000] {dagbag.py:348} ERROR - Failed to import: /opt/airflow/dags/read_dataset_dag.py
Traceback (most recent call last):
  File "/home/airflow/.local/lib/python3.8/site-packages/airflow/models/dagbag.py", line 344, in parse
    loader.exec_module(new_module)
  File "<frozen importlib._bootstrap_external>", line 843, in exec_module
  File "<frozen importlib._bootstrap>", line 219, in _call_with_frames_removed
  File "/opt/airflow/dags/read_dataset_dag.py", line 7, in <module>
    with DAG(
  File "/home/airflow/.local/lib/python3.8/site-packages/airflow/models/dag.py", line 600, in __init__
    self.timetable = create_timetable(schedule_interval, self.timezone)
  File "/home/airflow/.local/lib/python3.8/site-packages/airflow/models/dag.py", line 230, in create_timetable
    raise ValueError(f"{interval!r} is not a valid interval.")
ValueError: [Dataset(uri='tmp/my_file.txt', extra=None)] is not a valid interval.
[2024-01-04T20:57:28.748+0000] {processor.py:842} WARNING - No viable dags retrieved from /opt/airflow/dags/read_dataset_dag.py
[2024-01-04T20:57:28.773+0000] {processor.py:183} INFO - Processing /opt/airflow/dags/read_dataset_dag.py took 0.061 seconds
[2024-01-04T20:57:59.493+0000] {processor.py:161} INFO - Started process (PID=7398) to work on /opt/airflow/dags/read_dataset_dag.py
[2024-01-04T20:57:59.494+0000] {processor.py:830} INFO - Processing file /opt/airflow/dags/read_dataset_dag.py for tasks to queue
[2024-01-04T20:57:59.495+0000] {logging_mixin.py:188} INFO - [2024-01-04T20:57:59.495+0000] {dagbag.py:538} INFO - Filling up the DagBag from /opt/airflow/dags/read_dataset_dag.py
[2024-01-04T20:57:59.525+0000] {logging_mixin.py:188} INFO - [2024-01-04T20:57:59.518+0000] {dagbag.py:348} ERROR - Failed to import: /opt/airflow/dags/read_dataset_dag.py
Traceback (most recent call last):
  File "/home/airflow/.local/lib/python3.8/site-packages/airflow/models/dagbag.py", line 344, in parse
    loader.exec_module(new_module)
  File "<frozen importlib._bootstrap_external>", line 843, in exec_module
  File "<frozen importlib._bootstrap>", line 219, in _call_with_frames_removed
  File "/opt/airflow/dags/read_dataset_dag.py", line 7, in <module>
    with DAG(
  File "/home/airflow/.local/lib/python3.8/site-packages/airflow/models/dag.py", line 600, in __init__
    self.timetable = create_timetable(schedule_interval, self.timezone)
  File "/home/airflow/.local/lib/python3.8/site-packages/airflow/models/dag.py", line 230, in create_timetable
    raise ValueError(f"{interval!r} is not a valid interval.")
ValueError: [Dataset(uri='tmp/my_file.txt', extra=None)] is not a valid interval.
[2024-01-04T20:57:59.526+0000] {processor.py:842} WARNING - No viable dags retrieved from /opt/airflow/dags/read_dataset_dag.py
[2024-01-04T20:57:59.552+0000] {processor.py:183} INFO - Processing /opt/airflow/dags/read_dataset_dag.py took 0.062 seconds
[2024-01-04T20:58:30.391+0000] {processor.py:161} INFO - Started process (PID=7455) to work on /opt/airflow/dags/read_dataset_dag.py
[2024-01-04T20:58:30.411+0000] {processor.py:830} INFO - Processing file /opt/airflow/dags/read_dataset_dag.py for tasks to queue
[2024-01-04T20:58:30.415+0000] {logging_mixin.py:188} INFO - [2024-01-04T20:58:30.414+0000] {dagbag.py:538} INFO - Filling up the DagBag from /opt/airflow/dags/read_dataset_dag.py
[2024-01-04T20:58:30.511+0000] {logging_mixin.py:188} INFO - [2024-01-04T20:58:30.488+0000] {dagbag.py:348} ERROR - Failed to import: /opt/airflow/dags/read_dataset_dag.py
Traceback (most recent call last):
  File "/home/airflow/.local/lib/python3.8/site-packages/airflow/models/dagbag.py", line 344, in parse
    loader.exec_module(new_module)
  File "<frozen importlib._bootstrap_external>", line 843, in exec_module
  File "<frozen importlib._bootstrap>", line 219, in _call_with_frames_removed
  File "/opt/airflow/dags/read_dataset_dag.py", line 7, in <module>
    with DAG(
  File "/home/airflow/.local/lib/python3.8/site-packages/airflow/models/dag.py", line 600, in __init__
    self.timetable = create_timetable(schedule_interval, self.timezone)
  File "/home/airflow/.local/lib/python3.8/site-packages/airflow/models/dag.py", line 230, in create_timetable
    raise ValueError(f"{interval!r} is not a valid interval.")
ValueError: [Dataset(uri='tmp/my_file.txt', extra=None)] is not a valid interval.
[2024-01-04T20:58:30.513+0000] {processor.py:842} WARNING - No viable dags retrieved from /opt/airflow/dags/read_dataset_dag.py
[2024-01-04T20:58:30.568+0000] {processor.py:183} INFO - Processing /opt/airflow/dags/read_dataset_dag.py took 0.193 seconds
[2024-01-04T20:59:01.087+0000] {processor.py:161} INFO - Started process (PID=7515) to work on /opt/airflow/dags/read_dataset_dag.py
[2024-01-04T20:59:01.090+0000] {processor.py:830} INFO - Processing file /opt/airflow/dags/read_dataset_dag.py for tasks to queue
[2024-01-04T20:59:01.092+0000] {logging_mixin.py:188} INFO - [2024-01-04T20:59:01.091+0000] {dagbag.py:538} INFO - Filling up the DagBag from /opt/airflow/dags/read_dataset_dag.py
[2024-01-04T20:59:01.160+0000] {logging_mixin.py:188} INFO - [2024-01-04T20:59:01.113+0000] {dagbag.py:348} ERROR - Failed to import: /opt/airflow/dags/read_dataset_dag.py
Traceback (most recent call last):
  File "/home/airflow/.local/lib/python3.8/site-packages/airflow/models/dagbag.py", line 344, in parse
    loader.exec_module(new_module)
  File "<frozen importlib._bootstrap_external>", line 843, in exec_module
  File "<frozen importlib._bootstrap>", line 219, in _call_with_frames_removed
  File "/opt/airflow/dags/read_dataset_dag.py", line 7, in <module>
    with DAG(
  File "/home/airflow/.local/lib/python3.8/site-packages/airflow/models/dag.py", line 600, in __init__
    self.timetable = create_timetable(schedule_interval, self.timezone)
  File "/home/airflow/.local/lib/python3.8/site-packages/airflow/models/dag.py", line 230, in create_timetable
    raise ValueError(f"{interval!r} is not a valid interval.")
ValueError: [Dataset(uri='tmp/my_file.txt', extra=None)] is not a valid interval.
[2024-01-04T20:59:01.161+0000] {processor.py:842} WARNING - No viable dags retrieved from /opt/airflow/dags/read_dataset_dag.py
[2024-01-04T20:59:01.252+0000] {processor.py:183} INFO - Processing /opt/airflow/dags/read_dataset_dag.py took 0.169 seconds
[2024-01-04T20:59:31.932+0000] {processor.py:161} INFO - Started process (PID=7574) to work on /opt/airflow/dags/read_dataset_dag.py
[2024-01-04T20:59:31.934+0000] {processor.py:830} INFO - Processing file /opt/airflow/dags/read_dataset_dag.py for tasks to queue
[2024-01-04T20:59:31.935+0000] {logging_mixin.py:188} INFO - [2024-01-04T20:59:31.935+0000] {dagbag.py:538} INFO - Filling up the DagBag from /opt/airflow/dags/read_dataset_dag.py
[2024-01-04T20:59:31.965+0000] {logging_mixin.py:188} INFO - [2024-01-04T20:59:31.956+0000] {dagbag.py:348} ERROR - Failed to import: /opt/airflow/dags/read_dataset_dag.py
Traceback (most recent call last):
  File "/home/airflow/.local/lib/python3.8/site-packages/airflow/models/dagbag.py", line 344, in parse
    loader.exec_module(new_module)
  File "<frozen importlib._bootstrap_external>", line 843, in exec_module
  File "<frozen importlib._bootstrap>", line 219, in _call_with_frames_removed
  File "/opt/airflow/dags/read_dataset_dag.py", line 7, in <module>
    with DAG(
  File "/home/airflow/.local/lib/python3.8/site-packages/airflow/models/dag.py", line 600, in __init__
    self.timetable = create_timetable(schedule_interval, self.timezone)
  File "/home/airflow/.local/lib/python3.8/site-packages/airflow/models/dag.py", line 230, in create_timetable
    raise ValueError(f"{interval!r} is not a valid interval.")
ValueError: [Dataset(uri='tmp/my_file.txt', extra=None)] is not a valid interval.
[2024-01-04T20:59:31.966+0000] {processor.py:842} WARNING - No viable dags retrieved from /opt/airflow/dags/read_dataset_dag.py
[2024-01-04T20:59:31.995+0000] {processor.py:183} INFO - Processing /opt/airflow/dags/read_dataset_dag.py took 0.067 seconds
[2024-01-04T21:00:02.611+0000] {processor.py:161} INFO - Started process (PID=7633) to work on /opt/airflow/dags/read_dataset_dag.py
[2024-01-04T21:00:02.614+0000] {processor.py:830} INFO - Processing file /opt/airflow/dags/read_dataset_dag.py for tasks to queue
[2024-01-04T21:00:02.616+0000] {logging_mixin.py:188} INFO - [2024-01-04T21:00:02.616+0000] {dagbag.py:538} INFO - Filling up the DagBag from /opt/airflow/dags/read_dataset_dag.py
[2024-01-04T21:00:02.657+0000] {logging_mixin.py:188} INFO - [2024-01-04T21:00:02.646+0000] {dagbag.py:348} ERROR - Failed to import: /opt/airflow/dags/read_dataset_dag.py
Traceback (most recent call last):
  File "/home/airflow/.local/lib/python3.8/site-packages/airflow/models/dagbag.py", line 344, in parse
    loader.exec_module(new_module)
  File "<frozen importlib._bootstrap_external>", line 843, in exec_module
  File "<frozen importlib._bootstrap>", line 219, in _call_with_frames_removed
  File "/opt/airflow/dags/read_dataset_dag.py", line 7, in <module>
    with DAG(
  File "/home/airflow/.local/lib/python3.8/site-packages/airflow/models/dag.py", line 600, in __init__
    self.timetable = create_timetable(schedule_interval, self.timezone)
  File "/home/airflow/.local/lib/python3.8/site-packages/airflow/models/dag.py", line 230, in create_timetable
    raise ValueError(f"{interval!r} is not a valid interval.")
ValueError: [Dataset(uri='tmp/my_file.txt', extra=None)] is not a valid interval.
[2024-01-04T21:00:02.660+0000] {processor.py:842} WARNING - No viable dags retrieved from /opt/airflow/dags/read_dataset_dag.py
[2024-01-04T21:00:02.691+0000] {processor.py:183} INFO - Processing /opt/airflow/dags/read_dataset_dag.py took 0.087 seconds
[2024-01-04T21:00:33.072+0000] {processor.py:161} INFO - Started process (PID=7692) to work on /opt/airflow/dags/read_dataset_dag.py
[2024-01-04T21:00:33.073+0000] {processor.py:830} INFO - Processing file /opt/airflow/dags/read_dataset_dag.py for tasks to queue
[2024-01-04T21:00:33.075+0000] {logging_mixin.py:188} INFO - [2024-01-04T21:00:33.075+0000] {dagbag.py:538} INFO - Filling up the DagBag from /opt/airflow/dags/read_dataset_dag.py
[2024-01-04T21:00:33.116+0000] {logging_mixin.py:188} INFO - [2024-01-04T21:00:33.106+0000] {dagbag.py:348} ERROR - Failed to import: /opt/airflow/dags/read_dataset_dag.py
Traceback (most recent call last):
  File "/home/airflow/.local/lib/python3.8/site-packages/airflow/models/dagbag.py", line 344, in parse
    loader.exec_module(new_module)
  File "<frozen importlib._bootstrap_external>", line 843, in exec_module
  File "<frozen importlib._bootstrap>", line 219, in _call_with_frames_removed
  File "/opt/airflow/dags/read_dataset_dag.py", line 7, in <module>
    with DAG(
  File "/home/airflow/.local/lib/python3.8/site-packages/airflow/models/dag.py", line 600, in __init__
    self.timetable = create_timetable(schedule_interval, self.timezone)
  File "/home/airflow/.local/lib/python3.8/site-packages/airflow/models/dag.py", line 230, in create_timetable
    raise ValueError(f"{interval!r} is not a valid interval.")
ValueError: [Dataset(uri='tmp/my_file.txt', extra=None)] is not a valid interval.
[2024-01-04T21:00:33.117+0000] {processor.py:842} WARNING - No viable dags retrieved from /opt/airflow/dags/read_dataset_dag.py
[2024-01-04T21:00:33.155+0000] {processor.py:183} INFO - Processing /opt/airflow/dags/read_dataset_dag.py took 0.087 seconds
[2024-01-04T21:01:03.992+0000] {processor.py:161} INFO - Started process (PID=7751) to work on /opt/airflow/dags/read_dataset_dag.py
[2024-01-04T21:01:03.996+0000] {processor.py:830} INFO - Processing file /opt/airflow/dags/read_dataset_dag.py for tasks to queue
[2024-01-04T21:01:03.998+0000] {logging_mixin.py:188} INFO - [2024-01-04T21:01:03.997+0000] {dagbag.py:538} INFO - Filling up the DagBag from /opt/airflow/dags/read_dataset_dag.py
[2024-01-04T21:01:04.086+0000] {logging_mixin.py:188} INFO - [2024-01-04T21:01:04.029+0000] {dagbag.py:348} ERROR - Failed to import: /opt/airflow/dags/read_dataset_dag.py
Traceback (most recent call last):
  File "/home/airflow/.local/lib/python3.8/site-packages/airflow/models/dagbag.py", line 344, in parse
    loader.exec_module(new_module)
  File "<frozen importlib._bootstrap_external>", line 843, in exec_module
  File "<frozen importlib._bootstrap>", line 219, in _call_with_frames_removed
  File "/opt/airflow/dags/read_dataset_dag.py", line 7, in <module>
    with DAG(
  File "/home/airflow/.local/lib/python3.8/site-packages/airflow/models/dag.py", line 600, in __init__
    self.timetable = create_timetable(schedule_interval, self.timezone)
  File "/home/airflow/.local/lib/python3.8/site-packages/airflow/models/dag.py", line 230, in create_timetable
    raise ValueError(f"{interval!r} is not a valid interval.")
ValueError: [Dataset(uri='tmp/my_file.txt', extra=None)] is not a valid interval.
[2024-01-04T21:01:04.087+0000] {processor.py:842} WARNING - No viable dags retrieved from /opt/airflow/dags/read_dataset_dag.py
[2024-01-04T21:01:04.278+0000] {processor.py:183} INFO - Processing /opt/airflow/dags/read_dataset_dag.py took 0.292 seconds
[2024-01-04T21:01:34.334+0000] {processor.py:161} INFO - Started process (PID=7806) to work on /opt/airflow/dags/read_dataset_dag.py
[2024-01-04T21:01:34.335+0000] {processor.py:830} INFO - Processing file /opt/airflow/dags/read_dataset_dag.py for tasks to queue
[2024-01-04T21:01:34.337+0000] {logging_mixin.py:188} INFO - [2024-01-04T21:01:34.336+0000] {dagbag.py:538} INFO - Filling up the DagBag from /opt/airflow/dags/read_dataset_dag.py
[2024-01-04T21:01:34.365+0000] {logging_mixin.py:188} INFO - [2024-01-04T21:01:34.358+0000] {dagbag.py:348} ERROR - Failed to import: /opt/airflow/dags/read_dataset_dag.py
Traceback (most recent call last):
  File "/home/airflow/.local/lib/python3.8/site-packages/airflow/models/dagbag.py", line 344, in parse
    loader.exec_module(new_module)
  File "<frozen importlib._bootstrap_external>", line 843, in exec_module
  File "<frozen importlib._bootstrap>", line 219, in _call_with_frames_removed
  File "/opt/airflow/dags/read_dataset_dag.py", line 7, in <module>
    with DAG(
  File "/home/airflow/.local/lib/python3.8/site-packages/airflow/models/dag.py", line 600, in __init__
    self.timetable = create_timetable(schedule_interval, self.timezone)
  File "/home/airflow/.local/lib/python3.8/site-packages/airflow/models/dag.py", line 230, in create_timetable
    raise ValueError(f"{interval!r} is not a valid interval.")
ValueError: [Dataset(uri='tmp/my_file.txt', extra=None)] is not a valid interval.
[2024-01-04T21:01:34.366+0000] {processor.py:842} WARNING - No viable dags retrieved from /opt/airflow/dags/read_dataset_dag.py
[2024-01-04T21:01:34.389+0000] {processor.py:183} INFO - Processing /opt/airflow/dags/read_dataset_dag.py took 0.061 seconds
[2024-01-04T21:02:04.644+0000] {processor.py:161} INFO - Started process (PID=7865) to work on /opt/airflow/dags/read_dataset_dag.py
[2024-01-04T21:02:04.646+0000] {processor.py:830} INFO - Processing file /opt/airflow/dags/read_dataset_dag.py for tasks to queue
[2024-01-04T21:02:04.650+0000] {logging_mixin.py:188} INFO - [2024-01-04T21:02:04.648+0000] {dagbag.py:538} INFO - Filling up the DagBag from /opt/airflow/dags/read_dataset_dag.py
[2024-01-04T21:02:04.712+0000] {logging_mixin.py:188} INFO - [2024-01-04T21:02:04.698+0000] {dagbag.py:348} ERROR - Failed to import: /opt/airflow/dags/read_dataset_dag.py
Traceback (most recent call last):
  File "/home/airflow/.local/lib/python3.8/site-packages/airflow/models/dagbag.py", line 344, in parse
    loader.exec_module(new_module)
  File "<frozen importlib._bootstrap_external>", line 843, in exec_module
  File "<frozen importlib._bootstrap>", line 219, in _call_with_frames_removed
  File "/opt/airflow/dags/read_dataset_dag.py", line 7, in <module>
    with DAG(
  File "/home/airflow/.local/lib/python3.8/site-packages/airflow/models/dag.py", line 600, in __init__
    self.timetable = create_timetable(schedule_interval, self.timezone)
  File "/home/airflow/.local/lib/python3.8/site-packages/airflow/models/dag.py", line 230, in create_timetable
    raise ValueError(f"{interval!r} is not a valid interval.")
ValueError: [Dataset(uri='tmp/my_file.txt', extra=None)] is not a valid interval.
[2024-01-04T21:02:04.713+0000] {processor.py:842} WARNING - No viable dags retrieved from /opt/airflow/dags/read_dataset_dag.py
[2024-01-04T21:02:04.756+0000] {processor.py:183} INFO - Processing /opt/airflow/dags/read_dataset_dag.py took 0.123 seconds
[2024-01-04T21:02:35.121+0000] {processor.py:161} INFO - Started process (PID=7922) to work on /opt/airflow/dags/read_dataset_dag.py
[2024-01-04T21:02:35.122+0000] {processor.py:830} INFO - Processing file /opt/airflow/dags/read_dataset_dag.py for tasks to queue
[2024-01-04T21:02:35.124+0000] {logging_mixin.py:188} INFO - [2024-01-04T21:02:35.124+0000] {dagbag.py:538} INFO - Filling up the DagBag from /opt/airflow/dags/read_dataset_dag.py
[2024-01-04T21:02:35.160+0000] {logging_mixin.py:188} INFO - [2024-01-04T21:02:35.152+0000] {dagbag.py:348} ERROR - Failed to import: /opt/airflow/dags/read_dataset_dag.py
Traceback (most recent call last):
  File "/home/airflow/.local/lib/python3.8/site-packages/airflow/models/dagbag.py", line 344, in parse
    loader.exec_module(new_module)
  File "<frozen importlib._bootstrap_external>", line 843, in exec_module
  File "<frozen importlib._bootstrap>", line 219, in _call_with_frames_removed
  File "/opt/airflow/dags/read_dataset_dag.py", line 7, in <module>
    with DAG(
  File "/home/airflow/.local/lib/python3.8/site-packages/airflow/models/dag.py", line 600, in __init__
    self.timetable = create_timetable(schedule_interval, self.timezone)
  File "/home/airflow/.local/lib/python3.8/site-packages/airflow/models/dag.py", line 230, in create_timetable
    raise ValueError(f"{interval!r} is not a valid interval.")
ValueError: [Dataset(uri='tmp/my_file.txt', extra=None)] is not a valid interval.
[2024-01-04T21:02:35.162+0000] {processor.py:842} WARNING - No viable dags retrieved from /opt/airflow/dags/read_dataset_dag.py
[2024-01-04T21:02:35.193+0000] {processor.py:183} INFO - Processing /opt/airflow/dags/read_dataset_dag.py took 0.077 seconds
[2024-01-04T21:03:05.614+0000] {processor.py:161} INFO - Started process (PID=7981) to work on /opt/airflow/dags/read_dataset_dag.py
[2024-01-04T21:03:05.616+0000] {processor.py:830} INFO - Processing file /opt/airflow/dags/read_dataset_dag.py for tasks to queue
[2024-01-04T21:03:05.618+0000] {logging_mixin.py:188} INFO - [2024-01-04T21:03:05.617+0000] {dagbag.py:538} INFO - Filling up the DagBag from /opt/airflow/dags/read_dataset_dag.py
[2024-01-04T21:03:05.648+0000] {logging_mixin.py:188} INFO - [2024-01-04T21:03:05.642+0000] {dagbag.py:348} ERROR - Failed to import: /opt/airflow/dags/read_dataset_dag.py
Traceback (most recent call last):
  File "/home/airflow/.local/lib/python3.8/site-packages/airflow/models/dagbag.py", line 344, in parse
    loader.exec_module(new_module)
  File "<frozen importlib._bootstrap_external>", line 843, in exec_module
  File "<frozen importlib._bootstrap>", line 219, in _call_with_frames_removed
  File "/opt/airflow/dags/read_dataset_dag.py", line 7, in <module>
    with DAG(
  File "/home/airflow/.local/lib/python3.8/site-packages/airflow/models/dag.py", line 600, in __init__
    self.timetable = create_timetable(schedule_interval, self.timezone)
  File "/home/airflow/.local/lib/python3.8/site-packages/airflow/models/dag.py", line 230, in create_timetable
    raise ValueError(f"{interval!r} is not a valid interval.")
ValueError: [Dataset(uri='tmp/my_file.txt', extra=None)] is not a valid interval.
[2024-01-04T21:03:05.649+0000] {processor.py:842} WARNING - No viable dags retrieved from /opt/airflow/dags/read_dataset_dag.py
[2024-01-04T21:03:05.682+0000] {processor.py:183} INFO - Processing /opt/airflow/dags/read_dataset_dag.py took 0.072 seconds
[2024-01-04T21:03:35.819+0000] {processor.py:161} INFO - Started process (PID=8040) to work on /opt/airflow/dags/read_dataset_dag.py
[2024-01-04T21:03:35.822+0000] {processor.py:830} INFO - Processing file /opt/airflow/dags/read_dataset_dag.py for tasks to queue
[2024-01-04T21:03:35.823+0000] {logging_mixin.py:188} INFO - [2024-01-04T21:03:35.823+0000] {dagbag.py:538} INFO - Filling up the DagBag from /opt/airflow/dags/read_dataset_dag.py
[2024-01-04T21:03:35.862+0000] {logging_mixin.py:188} INFO - [2024-01-04T21:03:35.851+0000] {dagbag.py:348} ERROR - Failed to import: /opt/airflow/dags/read_dataset_dag.py
Traceback (most recent call last):
  File "/home/airflow/.local/lib/python3.8/site-packages/airflow/models/dagbag.py", line 344, in parse
    loader.exec_module(new_module)
  File "<frozen importlib._bootstrap_external>", line 843, in exec_module
  File "<frozen importlib._bootstrap>", line 219, in _call_with_frames_removed
  File "/opt/airflow/dags/read_dataset_dag.py", line 7, in <module>
    with DAG(
  File "/home/airflow/.local/lib/python3.8/site-packages/airflow/models/dag.py", line 600, in __init__
    self.timetable = create_timetable(schedule_interval, self.timezone)
  File "/home/airflow/.local/lib/python3.8/site-packages/airflow/models/dag.py", line 230, in create_timetable
    raise ValueError(f"{interval!r} is not a valid interval.")
ValueError: [Dataset(uri='tmp/my_file.txt', extra=None)] is not a valid interval.
[2024-01-04T21:03:35.863+0000] {processor.py:842} WARNING - No viable dags retrieved from /opt/airflow/dags/read_dataset_dag.py
[2024-01-04T21:03:35.896+0000] {processor.py:183} INFO - Processing /opt/airflow/dags/read_dataset_dag.py took 0.083 seconds
[2024-01-04T21:04:06.470+0000] {processor.py:161} INFO - Started process (PID=8097) to work on /opt/airflow/dags/read_dataset_dag.py
[2024-01-04T21:04:06.472+0000] {processor.py:830} INFO - Processing file /opt/airflow/dags/read_dataset_dag.py for tasks to queue
[2024-01-04T21:04:06.473+0000] {logging_mixin.py:188} INFO - [2024-01-04T21:04:06.473+0000] {dagbag.py:538} INFO - Filling up the DagBag from /opt/airflow/dags/read_dataset_dag.py
[2024-01-04T21:04:06.512+0000] {logging_mixin.py:188} INFO - [2024-01-04T21:04:06.501+0000] {dagbag.py:348} ERROR - Failed to import: /opt/airflow/dags/read_dataset_dag.py
Traceback (most recent call last):
  File "/home/airflow/.local/lib/python3.8/site-packages/airflow/models/dagbag.py", line 344, in parse
    loader.exec_module(new_module)
  File "<frozen importlib._bootstrap_external>", line 843, in exec_module
  File "<frozen importlib._bootstrap>", line 219, in _call_with_frames_removed
  File "/opt/airflow/dags/read_dataset_dag.py", line 7, in <module>
    with DAG(
  File "/home/airflow/.local/lib/python3.8/site-packages/airflow/models/dag.py", line 600, in __init__
    self.timetable = create_timetable(schedule_interval, self.timezone)
  File "/home/airflow/.local/lib/python3.8/site-packages/airflow/models/dag.py", line 230, in create_timetable
    raise ValueError(f"{interval!r} is not a valid interval.")
ValueError: [Dataset(uri='tmp/my_file.txt', extra=None)] is not a valid interval.
[2024-01-04T21:04:06.513+0000] {processor.py:842} WARNING - No viable dags retrieved from /opt/airflow/dags/read_dataset_dag.py
[2024-01-04T21:04:06.548+0000] {processor.py:183} INFO - Processing /opt/airflow/dags/read_dataset_dag.py took 0.085 seconds
[2024-01-04T21:04:37.236+0000] {processor.py:161} INFO - Started process (PID=8154) to work on /opt/airflow/dags/read_dataset_dag.py
[2024-01-04T21:04:37.240+0000] {processor.py:830} INFO - Processing file /opt/airflow/dags/read_dataset_dag.py for tasks to queue
[2024-01-04T21:04:37.243+0000] {logging_mixin.py:188} INFO - [2024-01-04T21:04:37.243+0000] {dagbag.py:538} INFO - Filling up the DagBag from /opt/airflow/dags/read_dataset_dag.py
[2024-01-04T21:04:37.293+0000] {logging_mixin.py:188} INFO - [2024-01-04T21:04:37.285+0000] {dagbag.py:348} ERROR - Failed to import: /opt/airflow/dags/read_dataset_dag.py
Traceback (most recent call last):
  File "/home/airflow/.local/lib/python3.8/site-packages/airflow/models/dagbag.py", line 344, in parse
    loader.exec_module(new_module)
  File "<frozen importlib._bootstrap_external>", line 843, in exec_module
  File "<frozen importlib._bootstrap>", line 219, in _call_with_frames_removed
  File "/opt/airflow/dags/read_dataset_dag.py", line 7, in <module>
    with DAG(
  File "/home/airflow/.local/lib/python3.8/site-packages/airflow/models/dag.py", line 600, in __init__
    self.timetable = create_timetable(schedule_interval, self.timezone)
  File "/home/airflow/.local/lib/python3.8/site-packages/airflow/models/dag.py", line 230, in create_timetable
    raise ValueError(f"{interval!r} is not a valid interval.")
ValueError: [Dataset(uri='tmp/my_file.txt', extra=None)] is not a valid interval.
[2024-01-04T21:04:37.294+0000] {processor.py:842} WARNING - No viable dags retrieved from /opt/airflow/dags/read_dataset_dag.py
[2024-01-04T21:04:37.374+0000] {processor.py:183} INFO - Processing /opt/airflow/dags/read_dataset_dag.py took 0.149 seconds
[2024-01-04T21:04:51.089+0000] {processor.py:161} INFO - Started process (PID=8199) to work on /opt/airflow/dags/read_dataset_dag.py
[2024-01-04T21:04:51.090+0000] {processor.py:830} INFO - Processing file /opt/airflow/dags/read_dataset_dag.py for tasks to queue
[2024-01-04T21:04:51.093+0000] {logging_mixin.py:188} INFO - [2024-01-04T21:04:51.092+0000] {dagbag.py:538} INFO - Filling up the DagBag from /opt/airflow/dags/read_dataset_dag.py
[2024-01-04T21:04:51.246+0000] {logging_mixin.py:188} INFO - [2024-01-04T21:04:51.230+0000] {dagbag.py:348} ERROR - Failed to import: /opt/airflow/dags/read_dataset_dag.py
Traceback (most recent call last):
  File "/home/airflow/.local/lib/python3.8/site-packages/airflow/models/dagbag.py", line 344, in parse
    loader.exec_module(new_module)
  File "<frozen importlib._bootstrap_external>", line 843, in exec_module
  File "<frozen importlib._bootstrap>", line 219, in _call_with_frames_removed
  File "/opt/airflow/dags/read_dataset_dag.py", line 4, in <module>
    from include.datasets import MY_FILE
  File "/opt/airflow/dags/include/datasets.py", line 1, in <module>
    from ariflow import Dataset
ModuleNotFoundError: No module named 'ariflow'
[2024-01-04T21:04:51.252+0000] {processor.py:842} WARNING - No viable dags retrieved from /opt/airflow/dags/read_dataset_dag.py
[2024-01-04T21:04:51.304+0000] {processor.py:183} INFO - Processing /opt/airflow/dags/read_dataset_dag.py took 0.221 seconds
[2024-01-04T21:05:12.366+0000] {processor.py:161} INFO - Started process (PID=8230) to work on /opt/airflow/dags/read_dataset_dag.py
[2024-01-04T21:05:12.373+0000] {processor.py:830} INFO - Processing file /opt/airflow/dags/read_dataset_dag.py for tasks to queue
[2024-01-04T21:05:12.378+0000] {logging_mixin.py:188} INFO - [2024-01-04T21:05:12.377+0000] {dagbag.py:538} INFO - Filling up the DagBag from /opt/airflow/dags/read_dataset_dag.py
[2024-01-04T21:05:12.529+0000] {logging_mixin.py:188} INFO - [2024-01-04T21:05:12.513+0000] {dagbag.py:348} ERROR - Failed to import: /opt/airflow/dags/read_dataset_dag.py
Traceback (most recent call last):
  File "/home/airflow/.local/lib/python3.8/site-packages/airflow/models/dagbag.py", line 344, in parse
    loader.exec_module(new_module)
  File "<frozen importlib._bootstrap_external>", line 843, in exec_module
  File "<frozen importlib._bootstrap>", line 219, in _call_with_frames_removed
  File "/opt/airflow/dags/read_dataset_dag.py", line 4, in <module>
    from include.datasets import MY_FILE
  File "/opt/airflow/dags/include/datasets.py", line 1, in <module>
    from ariflow import Dataset
ModuleNotFoundError: No module named 'ariflow'
[2024-01-04T21:05:12.534+0000] {processor.py:842} WARNING - No viable dags retrieved from /opt/airflow/dags/read_dataset_dag.py
[2024-01-04T21:05:12.584+0000] {processor.py:183} INFO - Processing /opt/airflow/dags/read_dataset_dag.py took 0.226 seconds
[2024-01-04T21:05:42.677+0000] {processor.py:161} INFO - Started process (PID=8288) to work on /opt/airflow/dags/read_dataset_dag.py
[2024-01-04T21:05:42.679+0000] {processor.py:830} INFO - Processing file /opt/airflow/dags/read_dataset_dag.py for tasks to queue
[2024-01-04T21:05:42.680+0000] {logging_mixin.py:188} INFO - [2024-01-04T21:05:42.679+0000] {dagbag.py:538} INFO - Filling up the DagBag from /opt/airflow/dags/read_dataset_dag.py
[2024-01-04T21:05:42.753+0000] {logging_mixin.py:188} INFO - [2024-01-04T21:05:42.744+0000] {dagbag.py:348} ERROR - Failed to import: /opt/airflow/dags/read_dataset_dag.py
Traceback (most recent call last):
  File "/home/airflow/.local/lib/python3.8/site-packages/airflow/models/dagbag.py", line 344, in parse
    loader.exec_module(new_module)
  File "<frozen importlib._bootstrap_external>", line 843, in exec_module
  File "<frozen importlib._bootstrap>", line 219, in _call_with_frames_removed
  File "/opt/airflow/dags/read_dataset_dag.py", line 6, in <module>
    with DAG(
  File "/home/airflow/.local/lib/python3.8/site-packages/airflow/models/dag.py", line 600, in __init__
    self.timetable = create_timetable(schedule_interval, self.timezone)
  File "/home/airflow/.local/lib/python3.8/site-packages/airflow/models/dag.py", line 230, in create_timetable
    raise ValueError(f"{interval!r} is not a valid interval.")
ValueError: [Dataset(uri='tmp/my_file.txt', extra=None)] is not a valid interval.
[2024-01-04T21:05:42.754+0000] {processor.py:842} WARNING - No viable dags retrieved from /opt/airflow/dags/read_dataset_dag.py
[2024-01-04T21:05:42.781+0000] {processor.py:183} INFO - Processing /opt/airflow/dags/read_dataset_dag.py took 0.107 seconds
[2024-01-04T21:06:12.839+0000] {processor.py:161} INFO - Started process (PID=8347) to work on /opt/airflow/dags/read_dataset_dag.py
[2024-01-04T21:06:12.840+0000] {processor.py:830} INFO - Processing file /opt/airflow/dags/read_dataset_dag.py for tasks to queue
[2024-01-04T21:06:12.842+0000] {logging_mixin.py:188} INFO - [2024-01-04T21:06:12.841+0000] {dagbag.py:538} INFO - Filling up the DagBag from /opt/airflow/dags/read_dataset_dag.py
[2024-01-04T21:06:12.910+0000] {logging_mixin.py:188} INFO - [2024-01-04T21:06:12.900+0000] {dagbag.py:348} ERROR - Failed to import: /opt/airflow/dags/read_dataset_dag.py
Traceback (most recent call last):
  File "/home/airflow/.local/lib/python3.8/site-packages/airflow/models/dagbag.py", line 344, in parse
    loader.exec_module(new_module)
  File "<frozen importlib._bootstrap_external>", line 843, in exec_module
  File "<frozen importlib._bootstrap>", line 219, in _call_with_frames_removed
  File "/opt/airflow/dags/read_dataset_dag.py", line 6, in <module>
    with DAG(
  File "/home/airflow/.local/lib/python3.8/site-packages/airflow/models/dag.py", line 600, in __init__
    self.timetable = create_timetable(schedule_interval, self.timezone)
  File "/home/airflow/.local/lib/python3.8/site-packages/airflow/models/dag.py", line 230, in create_timetable
    raise ValueError(f"{interval!r} is not a valid interval.")
ValueError: [Dataset(uri='tmp/my_file.txt', extra=None)] is not a valid interval.
[2024-01-04T21:06:12.911+0000] {processor.py:842} WARNING - No viable dags retrieved from /opt/airflow/dags/read_dataset_dag.py
[2024-01-04T21:06:12.937+0000] {processor.py:183} INFO - Processing /opt/airflow/dags/read_dataset_dag.py took 0.101 seconds
[2024-01-04T21:06:43.142+0000] {processor.py:161} INFO - Started process (PID=8405) to work on /opt/airflow/dags/read_dataset_dag.py
[2024-01-04T21:06:43.144+0000] {processor.py:830} INFO - Processing file /opt/airflow/dags/read_dataset_dag.py for tasks to queue
[2024-01-04T21:06:43.146+0000] {logging_mixin.py:188} INFO - [2024-01-04T21:06:43.145+0000] {dagbag.py:538} INFO - Filling up the DagBag from /opt/airflow/dags/read_dataset_dag.py
[2024-01-04T21:06:43.217+0000] {logging_mixin.py:188} INFO - [2024-01-04T21:06:43.206+0000] {dagbag.py:348} ERROR - Failed to import: /opt/airflow/dags/read_dataset_dag.py
Traceback (most recent call last):
  File "/home/airflow/.local/lib/python3.8/site-packages/airflow/models/dagbag.py", line 344, in parse
    loader.exec_module(new_module)
  File "<frozen importlib._bootstrap_external>", line 843, in exec_module
  File "<frozen importlib._bootstrap>", line 219, in _call_with_frames_removed
  File "/opt/airflow/dags/read_dataset_dag.py", line 6, in <module>
    with DAG(
  File "/home/airflow/.local/lib/python3.8/site-packages/airflow/models/dag.py", line 600, in __init__
    self.timetable = create_timetable(schedule_interval, self.timezone)
  File "/home/airflow/.local/lib/python3.8/site-packages/airflow/models/dag.py", line 230, in create_timetable
    raise ValueError(f"{interval!r} is not a valid interval.")
ValueError: [Dataset(uri='tmp/my_file.txt', extra=None)] is not a valid interval.
[2024-01-04T21:06:43.218+0000] {processor.py:842} WARNING - No viable dags retrieved from /opt/airflow/dags/read_dataset_dag.py
[2024-01-04T21:06:43.251+0000] {processor.py:183} INFO - Processing /opt/airflow/dags/read_dataset_dag.py took 0.113 seconds
[2024-01-04T21:07:14.447+0000] {processor.py:161} INFO - Started process (PID=8464) to work on /opt/airflow/dags/read_dataset_dag.py
[2024-01-04T21:07:14.449+0000] {processor.py:830} INFO - Processing file /opt/airflow/dags/read_dataset_dag.py for tasks to queue
[2024-01-04T21:07:14.451+0000] {logging_mixin.py:188} INFO - [2024-01-04T21:07:14.450+0000] {dagbag.py:538} INFO - Filling up the DagBag from /opt/airflow/dags/read_dataset_dag.py
[2024-01-04T21:07:14.527+0000] {logging_mixin.py:188} INFO - [2024-01-04T21:07:14.505+0000] {dagbag.py:348} ERROR - Failed to import: /opt/airflow/dags/read_dataset_dag.py
Traceback (most recent call last):
  File "/home/airflow/.local/lib/python3.8/site-packages/airflow/models/dagbag.py", line 344, in parse
    loader.exec_module(new_module)
  File "<frozen importlib._bootstrap_external>", line 843, in exec_module
  File "<frozen importlib._bootstrap>", line 219, in _call_with_frames_removed
  File "/opt/airflow/dags/read_dataset_dag.py", line 6, in <module>
    with DAG(
  File "/home/airflow/.local/lib/python3.8/site-packages/airflow/models/dag.py", line 600, in __init__
    self.timetable = create_timetable(schedule_interval, self.timezone)
  File "/home/airflow/.local/lib/python3.8/site-packages/airflow/models/dag.py", line 230, in create_timetable
    raise ValueError(f"{interval!r} is not a valid interval.")
ValueError: [Dataset(uri='tmp/my_file.txt', extra=None)] is not a valid interval.
[2024-01-04T21:07:14.528+0000] {processor.py:842} WARNING - No viable dags retrieved from /opt/airflow/dags/read_dataset_dag.py
[2024-01-04T21:07:14.568+0000] {processor.py:183} INFO - Processing /opt/airflow/dags/read_dataset_dag.py took 0.127 seconds
[2024-01-04T21:07:45.886+0000] {processor.py:161} INFO - Started process (PID=8511) to work on /opt/airflow/dags/read_dataset_dag.py
[2024-01-04T21:07:45.935+0000] {processor.py:830} INFO - Processing file /opt/airflow/dags/read_dataset_dag.py for tasks to queue
[2024-01-04T21:07:45.937+0000] {logging_mixin.py:188} INFO - [2024-01-04T21:07:45.936+0000] {dagbag.py:538} INFO - Filling up the DagBag from /opt/airflow/dags/read_dataset_dag.py
[2024-01-04T21:07:46.303+0000] {logging_mixin.py:188} INFO - [2024-01-04T21:07:46.162+0000] {dagbag.py:348} ERROR - Failed to import: /opt/airflow/dags/read_dataset_dag.py
Traceback (most recent call last):
  File "/home/airflow/.local/lib/python3.8/site-packages/airflow/models/dagbag.py", line 344, in parse
    loader.exec_module(new_module)
  File "<frozen importlib._bootstrap_external>", line 843, in exec_module
  File "<frozen importlib._bootstrap>", line 219, in _call_with_frames_removed
  File "/opt/airflow/dags/read_dataset_dag.py", line 6, in <module>
    with DAG(
  File "/home/airflow/.local/lib/python3.8/site-packages/airflow/models/dag.py", line 600, in __init__
    self.timetable = create_timetable(schedule_interval, self.timezone)
  File "/home/airflow/.local/lib/python3.8/site-packages/airflow/models/dag.py", line 230, in create_timetable
    raise ValueError(f"{interval!r} is not a valid interval.")
ValueError: [Dataset(uri='tmp/my_file.txt', extra=None)] is not a valid interval.
[2024-01-04T21:07:46.304+0000] {processor.py:842} WARNING - No viable dags retrieved from /opt/airflow/dags/read_dataset_dag.py
[2024-01-04T21:07:46.759+0000] {processor.py:183} INFO - Processing /opt/airflow/dags/read_dataset_dag.py took 0.877 seconds
[2024-01-04T21:08:17.191+0000] {processor.py:161} INFO - Started process (PID=8570) to work on /opt/airflow/dags/read_dataset_dag.py
[2024-01-04T21:08:17.193+0000] {processor.py:830} INFO - Processing file /opt/airflow/dags/read_dataset_dag.py for tasks to queue
[2024-01-04T21:08:17.197+0000] {logging_mixin.py:188} INFO - [2024-01-04T21:08:17.195+0000] {dagbag.py:538} INFO - Filling up the DagBag from /opt/airflow/dags/read_dataset_dag.py
[2024-01-04T21:08:17.259+0000] {logging_mixin.py:188} INFO - [2024-01-04T21:08:17.248+0000] {dagbag.py:348} ERROR - Failed to import: /opt/airflow/dags/read_dataset_dag.py
Traceback (most recent call last):
  File "/home/airflow/.local/lib/python3.8/site-packages/airflow/models/dagbag.py", line 344, in parse
    loader.exec_module(new_module)
  File "<frozen importlib._bootstrap_external>", line 843, in exec_module
  File "<frozen importlib._bootstrap>", line 219, in _call_with_frames_removed
  File "/opt/airflow/dags/read_dataset_dag.py", line 6, in <module>
    with DAG(
  File "/home/airflow/.local/lib/python3.8/site-packages/airflow/models/dag.py", line 600, in __init__
    self.timetable = create_timetable(schedule_interval, self.timezone)
  File "/home/airflow/.local/lib/python3.8/site-packages/airflow/models/dag.py", line 230, in create_timetable
    raise ValueError(f"{interval!r} is not a valid interval.")
ValueError: [Dataset(uri='tmp/my_file.txt', extra=None)] is not a valid interval.
[2024-01-04T21:08:17.260+0000] {processor.py:842} WARNING - No viable dags retrieved from /opt/airflow/dags/read_dataset_dag.py
[2024-01-04T21:08:17.304+0000] {processor.py:183} INFO - Processing /opt/airflow/dags/read_dataset_dag.py took 0.119 seconds
[2024-01-04T21:08:48.495+0000] {processor.py:161} INFO - Started process (PID=8628) to work on /opt/airflow/dags/read_dataset_dag.py
[2024-01-04T21:08:48.538+0000] {processor.py:830} INFO - Processing file /opt/airflow/dags/read_dataset_dag.py for tasks to queue
[2024-01-04T21:08:48.540+0000] {logging_mixin.py:188} INFO - [2024-01-04T21:08:48.540+0000] {dagbag.py:538} INFO - Filling up the DagBag from /opt/airflow/dags/read_dataset_dag.py
[2024-01-04T21:08:48.625+0000] {logging_mixin.py:188} INFO - [2024-01-04T21:08:48.614+0000] {dagbag.py:348} ERROR - Failed to import: /opt/airflow/dags/read_dataset_dag.py
Traceback (most recent call last):
  File "/home/airflow/.local/lib/python3.8/site-packages/airflow/models/dagbag.py", line 344, in parse
    loader.exec_module(new_module)
  File "<frozen importlib._bootstrap_external>", line 843, in exec_module
  File "<frozen importlib._bootstrap>", line 219, in _call_with_frames_removed
  File "/opt/airflow/dags/read_dataset_dag.py", line 6, in <module>
    with DAG(
  File "/home/airflow/.local/lib/python3.8/site-packages/airflow/models/dag.py", line 600, in __init__
    self.timetable = create_timetable(schedule_interval, self.timezone)
  File "/home/airflow/.local/lib/python3.8/site-packages/airflow/models/dag.py", line 230, in create_timetable
    raise ValueError(f"{interval!r} is not a valid interval.")
ValueError: [Dataset(uri='tmp/my_file.txt', extra=None)] is not a valid interval.
[2024-01-04T21:08:48.627+0000] {processor.py:842} WARNING - No viable dags retrieved from /opt/airflow/dags/read_dataset_dag.py
[2024-01-04T21:08:48.661+0000] {processor.py:183} INFO - Processing /opt/airflow/dags/read_dataset_dag.py took 0.173 seconds
[2024-01-04T21:09:19.390+0000] {processor.py:161} INFO - Started process (PID=8687) to work on /opt/airflow/dags/read_dataset_dag.py
[2024-01-04T21:09:19.392+0000] {processor.py:830} INFO - Processing file /opt/airflow/dags/read_dataset_dag.py for tasks to queue
[2024-01-04T21:09:19.394+0000] {logging_mixin.py:188} INFO - [2024-01-04T21:09:19.394+0000] {dagbag.py:538} INFO - Filling up the DagBag from /opt/airflow/dags/read_dataset_dag.py
[2024-01-04T21:09:19.444+0000] {logging_mixin.py:188} INFO - [2024-01-04T21:09:19.436+0000] {dagbag.py:348} ERROR - Failed to import: /opt/airflow/dags/read_dataset_dag.py
Traceback (most recent call last):
  File "/home/airflow/.local/lib/python3.8/site-packages/airflow/models/dagbag.py", line 344, in parse
    loader.exec_module(new_module)
  File "<frozen importlib._bootstrap_external>", line 843, in exec_module
  File "<frozen importlib._bootstrap>", line 219, in _call_with_frames_removed
  File "/opt/airflow/dags/read_dataset_dag.py", line 6, in <module>
    with DAG(
  File "/home/airflow/.local/lib/python3.8/site-packages/airflow/models/dag.py", line 600, in __init__
    self.timetable = create_timetable(schedule_interval, self.timezone)
  File "/home/airflow/.local/lib/python3.8/site-packages/airflow/models/dag.py", line 230, in create_timetable
    raise ValueError(f"{interval!r} is not a valid interval.")
ValueError: [Dataset(uri='tmp/my_file.txt', extra=None)] is not a valid interval.
[2024-01-04T21:09:19.446+0000] {processor.py:842} WARNING - No viable dags retrieved from /opt/airflow/dags/read_dataset_dag.py
[2024-01-04T21:09:19.474+0000] {processor.py:183} INFO - Processing /opt/airflow/dags/read_dataset_dag.py took 0.090 seconds
[2024-01-04T21:09:49.776+0000] {processor.py:161} INFO - Started process (PID=8746) to work on /opt/airflow/dags/read_dataset_dag.py
[2024-01-04T21:09:49.779+0000] {processor.py:830} INFO - Processing file /opt/airflow/dags/read_dataset_dag.py for tasks to queue
[2024-01-04T21:09:49.784+0000] {logging_mixin.py:188} INFO - [2024-01-04T21:09:49.782+0000] {dagbag.py:538} INFO - Filling up the DagBag from /opt/airflow/dags/read_dataset_dag.py
[2024-01-04T21:09:49.903+0000] {logging_mixin.py:188} INFO - [2024-01-04T21:09:49.849+0000] {dagbag.py:348} ERROR - Failed to import: /opt/airflow/dags/read_dataset_dag.py
Traceback (most recent call last):
  File "/home/airflow/.local/lib/python3.8/site-packages/airflow/models/dagbag.py", line 344, in parse
    loader.exec_module(new_module)
  File "<frozen importlib._bootstrap_external>", line 843, in exec_module
  File "<frozen importlib._bootstrap>", line 219, in _call_with_frames_removed
  File "/opt/airflow/dags/read_dataset_dag.py", line 6, in <module>
    with DAG(
  File "/home/airflow/.local/lib/python3.8/site-packages/airflow/models/dag.py", line 600, in __init__
    self.timetable = create_timetable(schedule_interval, self.timezone)
  File "/home/airflow/.local/lib/python3.8/site-packages/airflow/models/dag.py", line 230, in create_timetable
    raise ValueError(f"{interval!r} is not a valid interval.")
ValueError: [Dataset(uri='tmp/my_file.txt', extra=None)] is not a valid interval.
[2024-01-04T21:09:49.904+0000] {processor.py:842} WARNING - No viable dags retrieved from /opt/airflow/dags/read_dataset_dag.py
[2024-01-04T21:09:49.938+0000] {processor.py:183} INFO - Processing /opt/airflow/dags/read_dataset_dag.py took 0.168 seconds
[2024-01-04T21:10:20.564+0000] {processor.py:161} INFO - Started process (PID=8805) to work on /opt/airflow/dags/read_dataset_dag.py
[2024-01-04T21:10:20.566+0000] {processor.py:830} INFO - Processing file /opt/airflow/dags/read_dataset_dag.py for tasks to queue
[2024-01-04T21:10:20.567+0000] {logging_mixin.py:188} INFO - [2024-01-04T21:10:20.567+0000] {dagbag.py:538} INFO - Filling up the DagBag from /opt/airflow/dags/read_dataset_dag.py
[2024-01-04T21:10:20.614+0000] {logging_mixin.py:188} INFO - [2024-01-04T21:10:20.608+0000] {dagbag.py:348} ERROR - Failed to import: /opt/airflow/dags/read_dataset_dag.py
Traceback (most recent call last):
  File "/home/airflow/.local/lib/python3.8/site-packages/airflow/models/dagbag.py", line 344, in parse
    loader.exec_module(new_module)
  File "<frozen importlib._bootstrap_external>", line 843, in exec_module
  File "<frozen importlib._bootstrap>", line 219, in _call_with_frames_removed
  File "/opt/airflow/dags/read_dataset_dag.py", line 6, in <module>
    with DAG(
  File "/home/airflow/.local/lib/python3.8/site-packages/airflow/models/dag.py", line 600, in __init__
    self.timetable = create_timetable(schedule_interval, self.timezone)
  File "/home/airflow/.local/lib/python3.8/site-packages/airflow/models/dag.py", line 230, in create_timetable
    raise ValueError(f"{interval!r} is not a valid interval.")
ValueError: [Dataset(uri='tmp/my_file.txt', extra=None)] is not a valid interval.
[2024-01-04T21:10:20.615+0000] {processor.py:842} WARNING - No viable dags retrieved from /opt/airflow/dags/read_dataset_dag.py
[2024-01-04T21:10:20.651+0000] {processor.py:183} INFO - Processing /opt/airflow/dags/read_dataset_dag.py took 0.090 seconds
[2024-01-04T21:10:50.842+0000] {processor.py:161} INFO - Started process (PID=8864) to work on /opt/airflow/dags/read_dataset_dag.py
[2024-01-04T21:10:50.843+0000] {processor.py:830} INFO - Processing file /opt/airflow/dags/read_dataset_dag.py for tasks to queue
[2024-01-04T21:10:50.845+0000] {logging_mixin.py:188} INFO - [2024-01-04T21:10:50.844+0000] {dagbag.py:538} INFO - Filling up the DagBag from /opt/airflow/dags/read_dataset_dag.py
[2024-01-04T21:10:50.924+0000] {logging_mixin.py:188} INFO - [2024-01-04T21:10:50.914+0000] {dagbag.py:348} ERROR - Failed to import: /opt/airflow/dags/read_dataset_dag.py
Traceback (most recent call last):
  File "/home/airflow/.local/lib/python3.8/site-packages/airflow/models/dagbag.py", line 344, in parse
    loader.exec_module(new_module)
  File "<frozen importlib._bootstrap_external>", line 843, in exec_module
  File "<frozen importlib._bootstrap>", line 219, in _call_with_frames_removed
  File "/opt/airflow/dags/read_dataset_dag.py", line 6, in <module>
    with DAG(
  File "/home/airflow/.local/lib/python3.8/site-packages/airflow/models/dag.py", line 600, in __init__
    self.timetable = create_timetable(schedule_interval, self.timezone)
  File "/home/airflow/.local/lib/python3.8/site-packages/airflow/models/dag.py", line 230, in create_timetable
    raise ValueError(f"{interval!r} is not a valid interval.")
ValueError: [Dataset(uri='/tmp/my_file.txt', extra=None)] is not a valid interval.
[2024-01-04T21:10:50.926+0000] {processor.py:842} WARNING - No viable dags retrieved from /opt/airflow/dags/read_dataset_dag.py
[2024-01-04T21:10:50.969+0000] {processor.py:183} INFO - Processing /opt/airflow/dags/read_dataset_dag.py took 0.131 seconds
[2024-01-04T21:11:21.315+0000] {processor.py:161} INFO - Started process (PID=8922) to work on /opt/airflow/dags/read_dataset_dag.py
[2024-01-04T21:11:21.317+0000] {processor.py:830} INFO - Processing file /opt/airflow/dags/read_dataset_dag.py for tasks to queue
[2024-01-04T21:11:21.318+0000] {logging_mixin.py:188} INFO - [2024-01-04T21:11:21.318+0000] {dagbag.py:538} INFO - Filling up the DagBag from /opt/airflow/dags/read_dataset_dag.py
[2024-01-04T21:11:21.363+0000] {logging_mixin.py:188} INFO - [2024-01-04T21:11:21.356+0000] {dagbag.py:348} ERROR - Failed to import: /opt/airflow/dags/read_dataset_dag.py
Traceback (most recent call last):
  File "/home/airflow/.local/lib/python3.8/site-packages/airflow/models/dagbag.py", line 344, in parse
    loader.exec_module(new_module)
  File "<frozen importlib._bootstrap_external>", line 843, in exec_module
  File "<frozen importlib._bootstrap>", line 219, in _call_with_frames_removed
  File "/opt/airflow/dags/read_dataset_dag.py", line 6, in <module>
    with DAG(
  File "/home/airflow/.local/lib/python3.8/site-packages/airflow/models/dag.py", line 600, in __init__
    self.timetable = create_timetable(schedule_interval, self.timezone)
  File "/home/airflow/.local/lib/python3.8/site-packages/airflow/models/dag.py", line 230, in create_timetable
    raise ValueError(f"{interval!r} is not a valid interval.")
ValueError: [Dataset(uri='/tmp/my_file.txt', extra=None)] is not a valid interval.
[2024-01-04T21:11:21.363+0000] {processor.py:842} WARNING - No viable dags retrieved from /opt/airflow/dags/read_dataset_dag.py
[2024-01-04T21:11:21.388+0000] {processor.py:183} INFO - Processing /opt/airflow/dags/read_dataset_dag.py took 0.076 seconds
[2024-01-04T21:11:51.466+0000] {processor.py:161} INFO - Started process (PID=8981) to work on /opt/airflow/dags/read_dataset_dag.py
[2024-01-04T21:11:51.472+0000] {processor.py:830} INFO - Processing file /opt/airflow/dags/read_dataset_dag.py for tasks to queue
[2024-01-04T21:11:51.474+0000] {logging_mixin.py:188} INFO - [2024-01-04T21:11:51.473+0000] {dagbag.py:538} INFO - Filling up the DagBag from /opt/airflow/dags/read_dataset_dag.py
[2024-01-04T21:11:51.551+0000] {logging_mixin.py:188} INFO - [2024-01-04T21:11:51.528+0000] {dagbag.py:348} ERROR - Failed to import: /opt/airflow/dags/read_dataset_dag.py
Traceback (most recent call last):
  File "/home/airflow/.local/lib/python3.8/site-packages/airflow/models/dagbag.py", line 344, in parse
    loader.exec_module(new_module)
  File "<frozen importlib._bootstrap_external>", line 843, in exec_module
  File "<frozen importlib._bootstrap>", line 219, in _call_with_frames_removed
  File "/opt/airflow/dags/read_dataset_dag.py", line 6, in <module>
    with DAG(
  File "/home/airflow/.local/lib/python3.8/site-packages/airflow/models/dag.py", line 600, in __init__
    self.timetable = create_timetable(schedule_interval, self.timezone)
  File "/home/airflow/.local/lib/python3.8/site-packages/airflow/models/dag.py", line 230, in create_timetable
    raise ValueError(f"{interval!r} is not a valid interval.")
ValueError: [Dataset(uri='/tmp/my_file.txt', extra=None)] is not a valid interval.
[2024-01-04T21:11:51.552+0000] {processor.py:842} WARNING - No viable dags retrieved from /opt/airflow/dags/read_dataset_dag.py
[2024-01-04T21:11:52.257+0000] {processor.py:183} INFO - Processing /opt/airflow/dags/read_dataset_dag.py took 0.794 seconds
[2024-01-04T21:12:22.970+0000] {processor.py:161} INFO - Started process (PID=9039) to work on /opt/airflow/dags/read_dataset_dag.py
[2024-01-04T21:12:22.972+0000] {processor.py:830} INFO - Processing file /opt/airflow/dags/read_dataset_dag.py for tasks to queue
[2024-01-04T21:12:22.974+0000] {logging_mixin.py:188} INFO - [2024-01-04T21:12:22.974+0000] {dagbag.py:538} INFO - Filling up the DagBag from /opt/airflow/dags/read_dataset_dag.py
[2024-01-04T21:12:23.035+0000] {logging_mixin.py:188} INFO - [2024-01-04T21:12:23.027+0000] {dagbag.py:348} ERROR - Failed to import: /opt/airflow/dags/read_dataset_dag.py
Traceback (most recent call last):
  File "/home/airflow/.local/lib/python3.8/site-packages/airflow/models/dagbag.py", line 344, in parse
    loader.exec_module(new_module)
  File "<frozen importlib._bootstrap_external>", line 843, in exec_module
  File "<frozen importlib._bootstrap>", line 219, in _call_with_frames_removed
  File "/opt/airflow/dags/read_dataset_dag.py", line 6, in <module>
    with DAG(
  File "/home/airflow/.local/lib/python3.8/site-packages/airflow/models/dag.py", line 600, in __init__
    self.timetable = create_timetable(schedule_interval, self.timezone)
  File "/home/airflow/.local/lib/python3.8/site-packages/airflow/models/dag.py", line 230, in create_timetable
    raise ValueError(f"{interval!r} is not a valid interval.")
ValueError: [Dataset(uri='/tmp/my_file.txt', extra=None)] is not a valid interval.
[2024-01-04T21:12:23.036+0000] {processor.py:842} WARNING - No viable dags retrieved from /opt/airflow/dags/read_dataset_dag.py
[2024-01-04T21:12:23.067+0000] {processor.py:183} INFO - Processing /opt/airflow/dags/read_dataset_dag.py took 0.102 seconds
[2024-01-04T21:12:53.180+0000] {processor.py:161} INFO - Started process (PID=9098) to work on /opt/airflow/dags/read_dataset_dag.py
[2024-01-04T21:12:53.181+0000] {processor.py:830} INFO - Processing file /opt/airflow/dags/read_dataset_dag.py for tasks to queue
[2024-01-04T21:12:53.184+0000] {logging_mixin.py:188} INFO - [2024-01-04T21:12:53.183+0000] {dagbag.py:538} INFO - Filling up the DagBag from /opt/airflow/dags/read_dataset_dag.py
[2024-01-04T21:12:53.249+0000] {logging_mixin.py:188} INFO - [2024-01-04T21:12:53.240+0000] {dagbag.py:348} ERROR - Failed to import: /opt/airflow/dags/read_dataset_dag.py
Traceback (most recent call last):
  File "/home/airflow/.local/lib/python3.8/site-packages/airflow/models/dagbag.py", line 344, in parse
    loader.exec_module(new_module)
  File "<frozen importlib._bootstrap_external>", line 843, in exec_module
  File "<frozen importlib._bootstrap>", line 219, in _call_with_frames_removed
  File "/opt/airflow/dags/read_dataset_dag.py", line 6, in <module>
    with DAG(
  File "/home/airflow/.local/lib/python3.8/site-packages/airflow/models/dag.py", line 600, in __init__
    self.timetable = create_timetable(schedule_interval, self.timezone)
  File "/home/airflow/.local/lib/python3.8/site-packages/airflow/models/dag.py", line 230, in create_timetable
    raise ValueError(f"{interval!r} is not a valid interval.")
ValueError: [Dataset(uri='/tmp/my_file.txt', extra=None)] is not a valid interval.
[2024-01-04T21:12:53.250+0000] {processor.py:842} WARNING - No viable dags retrieved from /opt/airflow/dags/read_dataset_dag.py
[2024-01-04T21:12:53.276+0000] {processor.py:183} INFO - Processing /opt/airflow/dags/read_dataset_dag.py took 0.102 seconds
[2024-01-04T21:13:23.654+0000] {processor.py:161} INFO - Started process (PID=9157) to work on /opt/airflow/dags/read_dataset_dag.py
[2024-01-04T21:13:23.656+0000] {processor.py:830} INFO - Processing file /opt/airflow/dags/read_dataset_dag.py for tasks to queue
[2024-01-04T21:13:23.659+0000] {logging_mixin.py:188} INFO - [2024-01-04T21:13:23.658+0000] {dagbag.py:538} INFO - Filling up the DagBag from /opt/airflow/dags/read_dataset_dag.py
[2024-01-04T21:13:23.745+0000] {logging_mixin.py:188} INFO - [2024-01-04T21:13:23.725+0000] {dagbag.py:348} ERROR - Failed to import: /opt/airflow/dags/read_dataset_dag.py
Traceback (most recent call last):
  File "/home/airflow/.local/lib/python3.8/site-packages/airflow/models/dagbag.py", line 344, in parse
    loader.exec_module(new_module)
  File "<frozen importlib._bootstrap_external>", line 843, in exec_module
  File "<frozen importlib._bootstrap>", line 219, in _call_with_frames_removed
  File "/opt/airflow/dags/read_dataset_dag.py", line 6, in <module>
    with DAG(
  File "/home/airflow/.local/lib/python3.8/site-packages/airflow/models/dag.py", line 600, in __init__
    self.timetable = create_timetable(schedule_interval, self.timezone)
  File "/home/airflow/.local/lib/python3.8/site-packages/airflow/models/dag.py", line 230, in create_timetable
    raise ValueError(f"{interval!r} is not a valid interval.")
ValueError: [Dataset(uri='/tmp/my_file.txt', extra=None)] is not a valid interval.
[2024-01-04T21:13:23.746+0000] {processor.py:842} WARNING - No viable dags retrieved from /opt/airflow/dags/read_dataset_dag.py
[2024-01-04T21:13:23.789+0000] {processor.py:183} INFO - Processing /opt/airflow/dags/read_dataset_dag.py took 0.142 seconds
[2024-01-04T21:13:54.497+0000] {processor.py:161} INFO - Started process (PID=9216) to work on /opt/airflow/dags/read_dataset_dag.py
[2024-01-04T21:13:54.505+0000] {processor.py:830} INFO - Processing file /opt/airflow/dags/read_dataset_dag.py for tasks to queue
[2024-01-04T21:13:54.509+0000] {logging_mixin.py:188} INFO - [2024-01-04T21:13:54.508+0000] {dagbag.py:538} INFO - Filling up the DagBag from /opt/airflow/dags/read_dataset_dag.py
[2024-01-04T21:13:54.631+0000] {logging_mixin.py:188} INFO - [2024-01-04T21:13:54.618+0000] {dagbag.py:348} ERROR - Failed to import: /opt/airflow/dags/read_dataset_dag.py
Traceback (most recent call last):
  File "/home/airflow/.local/lib/python3.8/site-packages/airflow/models/dagbag.py", line 344, in parse
    loader.exec_module(new_module)
  File "<frozen importlib._bootstrap_external>", line 843, in exec_module
  File "<frozen importlib._bootstrap>", line 219, in _call_with_frames_removed
  File "/opt/airflow/dags/read_dataset_dag.py", line 6, in <module>
    with DAG(
  File "/home/airflow/.local/lib/python3.8/site-packages/airflow/models/dag.py", line 600, in __init__
    self.timetable = create_timetable(schedule_interval, self.timezone)
  File "/home/airflow/.local/lib/python3.8/site-packages/airflow/models/dag.py", line 230, in create_timetable
    raise ValueError(f"{interval!r} is not a valid interval.")
ValueError: [Dataset(uri='/tmp/my_file.txt', extra=None)] is not a valid interval.
[2024-01-04T21:13:54.632+0000] {processor.py:842} WARNING - No viable dags retrieved from /opt/airflow/dags/read_dataset_dag.py
[2024-01-04T21:13:54.682+0000] {processor.py:183} INFO - Processing /opt/airflow/dags/read_dataset_dag.py took 0.192 seconds
[2024-01-04T21:14:24.774+0000] {processor.py:161} INFO - Started process (PID=9275) to work on /opt/airflow/dags/read_dataset_dag.py
[2024-01-04T21:14:24.780+0000] {processor.py:830} INFO - Processing file /opt/airflow/dags/read_dataset_dag.py for tasks to queue
[2024-01-04T21:14:24.783+0000] {logging_mixin.py:188} INFO - [2024-01-04T21:14:24.782+0000] {dagbag.py:538} INFO - Filling up the DagBag from /opt/airflow/dags/read_dataset_dag.py
[2024-01-04T21:14:24.876+0000] {logging_mixin.py:188} INFO - [2024-01-04T21:14:24.868+0000] {dagbag.py:348} ERROR - Failed to import: /opt/airflow/dags/read_dataset_dag.py
Traceback (most recent call last):
  File "/home/airflow/.local/lib/python3.8/site-packages/airflow/models/dagbag.py", line 344, in parse
    loader.exec_module(new_module)
  File "<frozen importlib._bootstrap_external>", line 843, in exec_module
  File "<frozen importlib._bootstrap>", line 219, in _call_with_frames_removed
  File "/opt/airflow/dags/read_dataset_dag.py", line 6, in <module>
    with DAG(
  File "/home/airflow/.local/lib/python3.8/site-packages/airflow/models/dag.py", line 600, in __init__
    self.timetable = create_timetable(schedule_interval, self.timezone)
  File "/home/airflow/.local/lib/python3.8/site-packages/airflow/models/dag.py", line 230, in create_timetable
    raise ValueError(f"{interval!r} is not a valid interval.")
ValueError: [Dataset(uri='/tmp/my_file.txt', extra=None)] is not a valid interval.
[2024-01-04T21:14:24.877+0000] {processor.py:842} WARNING - No viable dags retrieved from /opt/airflow/dags/read_dataset_dag.py
[2024-01-04T21:14:24.908+0000] {processor.py:183} INFO - Processing /opt/airflow/dags/read_dataset_dag.py took 0.144 seconds
[2024-01-04T21:14:55.215+0000] {processor.py:161} INFO - Started process (PID=9333) to work on /opt/airflow/dags/read_dataset_dag.py
[2024-01-04T21:14:55.218+0000] {processor.py:830} INFO - Processing file /opt/airflow/dags/read_dataset_dag.py for tasks to queue
[2024-01-04T21:14:55.220+0000] {logging_mixin.py:188} INFO - [2024-01-04T21:14:55.219+0000] {dagbag.py:538} INFO - Filling up the DagBag from /opt/airflow/dags/read_dataset_dag.py
[2024-01-04T21:14:55.291+0000] {logging_mixin.py:188} INFO - [2024-01-04T21:14:55.277+0000] {dagbag.py:348} ERROR - Failed to import: /opt/airflow/dags/read_dataset_dag.py
Traceback (most recent call last):
  File "/home/airflow/.local/lib/python3.8/site-packages/airflow/models/dagbag.py", line 344, in parse
    loader.exec_module(new_module)
  File "<frozen importlib._bootstrap_external>", line 843, in exec_module
  File "<frozen importlib._bootstrap>", line 219, in _call_with_frames_removed
  File "/opt/airflow/dags/read_dataset_dag.py", line 6, in <module>
    with DAG(
  File "/home/airflow/.local/lib/python3.8/site-packages/airflow/models/dag.py", line 600, in __init__
    self.timetable = create_timetable(schedule_interval, self.timezone)
  File "/home/airflow/.local/lib/python3.8/site-packages/airflow/models/dag.py", line 230, in create_timetable
    raise ValueError(f"{interval!r} is not a valid interval.")
ValueError: [Dataset(uri='/tmp/my_file.txt', extra=None)] is not a valid interval.
[2024-01-04T21:14:55.292+0000] {processor.py:842} WARNING - No viable dags retrieved from /opt/airflow/dags/read_dataset_dag.py
[2024-01-04T21:14:55.331+0000] {processor.py:183} INFO - Processing /opt/airflow/dags/read_dataset_dag.py took 0.125 seconds
[2024-01-04T21:15:25.928+0000] {processor.py:161} INFO - Started process (PID=9392) to work on /opt/airflow/dags/read_dataset_dag.py
[2024-01-04T21:15:25.931+0000] {processor.py:830} INFO - Processing file /opt/airflow/dags/read_dataset_dag.py for tasks to queue
[2024-01-04T21:15:25.933+0000] {logging_mixin.py:188} INFO - [2024-01-04T21:15:25.932+0000] {dagbag.py:538} INFO - Filling up the DagBag from /opt/airflow/dags/read_dataset_dag.py
[2024-01-04T21:15:26.005+0000] {logging_mixin.py:188} INFO - [2024-01-04T21:15:25.996+0000] {dagbag.py:348} ERROR - Failed to import: /opt/airflow/dags/read_dataset_dag.py
Traceback (most recent call last):
  File "/home/airflow/.local/lib/python3.8/site-packages/airflow/models/dagbag.py", line 344, in parse
    loader.exec_module(new_module)
  File "<frozen importlib._bootstrap_external>", line 843, in exec_module
  File "<frozen importlib._bootstrap>", line 219, in _call_with_frames_removed
  File "/opt/airflow/dags/read_dataset_dag.py", line 6, in <module>
    with DAG(
  File "/home/airflow/.local/lib/python3.8/site-packages/airflow/models/dag.py", line 600, in __init__
    self.timetable = create_timetable(schedule_interval, self.timezone)
  File "/home/airflow/.local/lib/python3.8/site-packages/airflow/models/dag.py", line 230, in create_timetable
    raise ValueError(f"{interval!r} is not a valid interval.")
ValueError: [Dataset(uri='/tmp/my_file.txt', extra=None)] is not a valid interval.
[2024-01-04T21:15:26.006+0000] {processor.py:842} WARNING - No viable dags retrieved from /opt/airflow/dags/read_dataset_dag.py
[2024-01-04T21:15:26.044+0000] {processor.py:183} INFO - Processing /opt/airflow/dags/read_dataset_dag.py took 0.122 seconds
[2024-01-04T21:15:56.247+0000] {processor.py:161} INFO - Started process (PID=9451) to work on /opt/airflow/dags/read_dataset_dag.py
[2024-01-04T21:15:56.253+0000] {processor.py:830} INFO - Processing file /opt/airflow/dags/read_dataset_dag.py for tasks to queue
[2024-01-04T21:15:56.256+0000] {logging_mixin.py:188} INFO - [2024-01-04T21:15:56.255+0000] {dagbag.py:538} INFO - Filling up the DagBag from /opt/airflow/dags/read_dataset_dag.py
[2024-01-04T21:15:56.352+0000] {logging_mixin.py:188} INFO - [2024-01-04T21:15:56.342+0000] {dagbag.py:348} ERROR - Failed to import: /opt/airflow/dags/read_dataset_dag.py
Traceback (most recent call last):
  File "/home/airflow/.local/lib/python3.8/site-packages/airflow/models/dagbag.py", line 344, in parse
    loader.exec_module(new_module)
  File "<frozen importlib._bootstrap_external>", line 843, in exec_module
  File "<frozen importlib._bootstrap>", line 219, in _call_with_frames_removed
  File "/opt/airflow/dags/read_dataset_dag.py", line 6, in <module>
    with DAG(
  File "/home/airflow/.local/lib/python3.8/site-packages/airflow/models/dag.py", line 600, in __init__
    self.timetable = create_timetable(schedule_interval, self.timezone)
  File "/home/airflow/.local/lib/python3.8/site-packages/airflow/models/dag.py", line 230, in create_timetable
    raise ValueError(f"{interval!r} is not a valid interval.")
ValueError: [Dataset(uri='/tmp/my_file.txt', extra=None)] is not a valid interval.
[2024-01-04T21:15:56.353+0000] {processor.py:842} WARNING - No viable dags retrieved from /opt/airflow/dags/read_dataset_dag.py
[2024-01-04T21:15:56.377+0000] {processor.py:183} INFO - Processing /opt/airflow/dags/read_dataset_dag.py took 0.138 seconds
[2024-01-04T21:16:20.462+0000] {processor.py:161} INFO - Started process (PID=9496) to work on /opt/airflow/dags/read_dataset_dag.py
[2024-01-04T21:16:20.464+0000] {processor.py:830} INFO - Processing file /opt/airflow/dags/read_dataset_dag.py for tasks to queue
[2024-01-04T21:16:20.466+0000] {logging_mixin.py:188} INFO - [2024-01-04T21:16:20.465+0000] {dagbag.py:538} INFO - Filling up the DagBag from /opt/airflow/dags/read_dataset_dag.py
[2024-01-04T21:16:20.566+0000] {processor.py:840} INFO - DAG(s) 'read_dag_dataset' retrieved from /opt/airflow/dags/read_dataset_dag.py
[2024-01-04T21:16:21.221+0000] {logging_mixin.py:188} INFO - [2024-01-04T21:16:21.220+0000] {override.py:1769} INFO - Created Permission View: can delete on DAG:read_dag_dataset
[2024-01-04T21:16:21.248+0000] {logging_mixin.py:188} INFO - [2024-01-04T21:16:21.247+0000] {override.py:1769} INFO - Created Permission View: can read on DAG:read_dag_dataset
[2024-01-04T21:16:21.267+0000] {logging_mixin.py:188} INFO - [2024-01-04T21:16:21.267+0000] {override.py:1769} INFO - Created Permission View: can edit on DAG:read_dag_dataset
[2024-01-04T21:16:21.274+0000] {logging_mixin.py:188} INFO - [2024-01-04T21:16:21.273+0000] {dag.py:3033} INFO - Sync 1 DAGs
[2024-01-04T21:16:21.359+0000] {logging_mixin.py:188} INFO - [2024-01-04T21:16:21.359+0000] {dag.py:3055} INFO - Creating ORM DAG for read_dag_dataset
[2024-01-04T21:16:21.419+0000] {logging_mixin.py:188} INFO - [2024-01-04T21:16:21.418+0000] {dag.py:3820} INFO - Setting next_dagrun for read_dag_dataset to None, run_after=None
[2024-01-04T21:16:21.640+0000] {processor.py:183} INFO - Processing /opt/airflow/dags/read_dataset_dag.py took 1.184 seconds
[2024-01-04T21:16:27.328+0000] {processor.py:161} INFO - Started process (PID=9513) to work on /opt/airflow/dags/read_dataset_dag.py
[2024-01-04T21:16:27.333+0000] {processor.py:830} INFO - Processing file /opt/airflow/dags/read_dataset_dag.py for tasks to queue
[2024-01-04T21:16:27.336+0000] {logging_mixin.py:188} INFO - [2024-01-04T21:16:27.335+0000] {dagbag.py:538} INFO - Filling up the DagBag from /opt/airflow/dags/read_dataset_dag.py
[2024-01-04T21:16:27.440+0000] {processor.py:840} INFO - DAG(s) 'read_dag_dataset' retrieved from /opt/airflow/dags/read_dataset_dag.py
[2024-01-04T21:16:27.488+0000] {logging_mixin.py:188} INFO - [2024-01-04T21:16:27.488+0000] {dag.py:3033} INFO - Sync 1 DAGs
[2024-01-04T21:16:27.853+0000] {logging_mixin.py:188} INFO - [2024-01-04T21:16:27.853+0000] {dag.py:3820} INFO - Setting next_dagrun for read_dag_dataset to None, run_after=None
[2024-01-04T21:16:27.921+0000] {processor.py:183} INFO - Processing /opt/airflow/dags/read_dataset_dag.py took 0.600 seconds
[2024-01-04T21:17:47.754+0000] {processor.py:161} INFO - Started process (PID=9572) to work on /opt/airflow/dags/read_dataset_dag.py
[2024-01-04T21:17:47.793+0000] {processor.py:830} INFO - Processing file /opt/airflow/dags/read_dataset_dag.py for tasks to queue
[2024-01-04T21:17:47.795+0000] {logging_mixin.py:188} INFO - [2024-01-04T21:17:47.795+0000] {dagbag.py:538} INFO - Filling up the DagBag from /opt/airflow/dags/read_dataset_dag.py
[2024-01-04T21:17:48.371+0000] {processor.py:840} INFO - DAG(s) 'read_dag_dataset' retrieved from /opt/airflow/dags/read_dataset_dag.py
[2024-01-04T21:17:51.297+0000] {logging_mixin.py:188} INFO - [2024-01-04T21:17:51.297+0000] {dag.py:3033} INFO - Sync 1 DAGs
[2024-01-04T21:17:51.338+0000] {logging_mixin.py:188} INFO - [2024-01-04T21:17:51.337+0000] {dag.py:3820} INFO - Setting next_dagrun for read_dag_dataset to None, run_after=None
[2024-01-04T21:17:51.444+0000] {processor.py:183} INFO - Processing /opt/airflow/dags/read_dataset_dag.py took 3.996 seconds
[2024-01-04T21:19:03.273+0000] {processor.py:161} INFO - Started process (PID=9633) to work on /opt/airflow/dags/read_dataset_dag.py
[2024-01-04T21:19:03.281+0000] {processor.py:830} INFO - Processing file /opt/airflow/dags/read_dataset_dag.py for tasks to queue
[2024-01-04T21:19:03.287+0000] {logging_mixin.py:188} INFO - [2024-01-04T21:19:03.284+0000] {dagbag.py:538} INFO - Filling up the DagBag from /opt/airflow/dags/read_dataset_dag.py
[2024-01-04T21:19:03.541+0000] {processor.py:840} INFO - DAG(s) 'read_dag_dataset' retrieved from /opt/airflow/dags/read_dataset_dag.py
[2024-01-04T21:19:05.225+0000] {logging_mixin.py:188} INFO - [2024-01-04T21:19:05.224+0000] {dag.py:3033} INFO - Sync 1 DAGs
[2024-01-04T21:19:05.337+0000] {logging_mixin.py:188} INFO - [2024-01-04T21:19:05.336+0000] {dag.py:3820} INFO - Setting next_dagrun for read_dag_dataset to None, run_after=None
[2024-01-04T21:19:05.417+0000] {processor.py:183} INFO - Processing /opt/airflow/dags/read_dataset_dag.py took 1.815 seconds
[2024-01-04T21:19:36.390+0000] {processor.py:161} INFO - Started process (PID=9697) to work on /opt/airflow/dags/read_dataset_dag.py
[2024-01-04T21:19:36.391+0000] {processor.py:830} INFO - Processing file /opt/airflow/dags/read_dataset_dag.py for tasks to queue
[2024-01-04T21:19:36.393+0000] {logging_mixin.py:188} INFO - [2024-01-04T21:19:36.392+0000] {dagbag.py:538} INFO - Filling up the DagBag from /opt/airflow/dags/read_dataset_dag.py
[2024-01-04T21:19:36.467+0000] {processor.py:840} INFO - DAG(s) 'read_dag_dataset' retrieved from /opt/airflow/dags/read_dataset_dag.py
[2024-01-04T21:19:36.503+0000] {logging_mixin.py:188} INFO - [2024-01-04T21:19:36.503+0000] {dag.py:3033} INFO - Sync 1 DAGs
[2024-01-04T21:19:36.548+0000] {logging_mixin.py:188} INFO - [2024-01-04T21:19:36.547+0000] {dag.py:3820} INFO - Setting next_dagrun for read_dag_dataset to None, run_after=None
[2024-01-04T21:19:36.595+0000] {processor.py:183} INFO - Processing /opt/airflow/dags/read_dataset_dag.py took 0.210 seconds
[2024-01-04T21:20:06.686+0000] {processor.py:161} INFO - Started process (PID=9754) to work on /opt/airflow/dags/read_dataset_dag.py
[2024-01-04T21:20:06.687+0000] {processor.py:830} INFO - Processing file /opt/airflow/dags/read_dataset_dag.py for tasks to queue
[2024-01-04T21:20:06.689+0000] {logging_mixin.py:188} INFO - [2024-01-04T21:20:06.688+0000] {dagbag.py:538} INFO - Filling up the DagBag from /opt/airflow/dags/read_dataset_dag.py
[2024-01-04T21:20:06.740+0000] {processor.py:840} INFO - DAG(s) 'read_dag_dataset' retrieved from /opt/airflow/dags/read_dataset_dag.py
[2024-01-04T21:20:06.766+0000] {logging_mixin.py:188} INFO - [2024-01-04T21:20:06.765+0000] {dag.py:3033} INFO - Sync 1 DAGs
[2024-01-04T21:20:06.797+0000] {logging_mixin.py:188} INFO - [2024-01-04T21:20:06.797+0000] {dag.py:3820} INFO - Setting next_dagrun for read_dag_dataset to None, run_after=None
[2024-01-04T21:20:06.844+0000] {processor.py:183} INFO - Processing /opt/airflow/dags/read_dataset_dag.py took 0.162 seconds
[2024-01-04T21:20:37.360+0000] {processor.py:161} INFO - Started process (PID=9813) to work on /opt/airflow/dags/read_dataset_dag.py
[2024-01-04T21:20:37.362+0000] {processor.py:830} INFO - Processing file /opt/airflow/dags/read_dataset_dag.py for tasks to queue
[2024-01-04T21:20:37.364+0000] {logging_mixin.py:188} INFO - [2024-01-04T21:20:37.363+0000] {dagbag.py:538} INFO - Filling up the DagBag from /opt/airflow/dags/read_dataset_dag.py
[2024-01-04T21:20:37.416+0000] {processor.py:840} INFO - DAG(s) 'read_dag_dataset' retrieved from /opt/airflow/dags/read_dataset_dag.py
[2024-01-04T21:20:37.454+0000] {logging_mixin.py:188} INFO - [2024-01-04T21:20:37.454+0000] {dag.py:3033} INFO - Sync 1 DAGs
[2024-01-04T21:20:37.488+0000] {logging_mixin.py:188} INFO - [2024-01-04T21:20:37.488+0000] {dag.py:3820} INFO - Setting next_dagrun for read_dag_dataset to None, run_after=None
[2024-01-04T21:20:37.533+0000] {processor.py:183} INFO - Processing /opt/airflow/dags/read_dataset_dag.py took 0.177 seconds
[2024-01-04T21:21:08.013+0000] {processor.py:161} INFO - Started process (PID=9872) to work on /opt/airflow/dags/read_dataset_dag.py
[2024-01-04T21:21:08.015+0000] {processor.py:830} INFO - Processing file /opt/airflow/dags/read_dataset_dag.py for tasks to queue
[2024-01-04T21:21:08.017+0000] {logging_mixin.py:188} INFO - [2024-01-04T21:21:08.016+0000] {dagbag.py:538} INFO - Filling up the DagBag from /opt/airflow/dags/read_dataset_dag.py
[2024-01-04T21:21:08.062+0000] {processor.py:840} INFO - DAG(s) 'read_dag_dataset' retrieved from /opt/airflow/dags/read_dataset_dag.py
[2024-01-04T21:21:08.090+0000] {logging_mixin.py:188} INFO - [2024-01-04T21:21:08.090+0000] {dag.py:3033} INFO - Sync 1 DAGs
[2024-01-04T21:21:08.115+0000] {logging_mixin.py:188} INFO - [2024-01-04T21:21:08.115+0000] {dag.py:3820} INFO - Setting next_dagrun for read_dag_dataset to None, run_after=None
[2024-01-04T21:21:08.154+0000] {processor.py:183} INFO - Processing /opt/airflow/dags/read_dataset_dag.py took 0.146 seconds
[2024-01-04T21:21:38.582+0000] {processor.py:161} INFO - Started process (PID=9931) to work on /opt/airflow/dags/read_dataset_dag.py
[2024-01-04T21:21:38.587+0000] {processor.py:830} INFO - Processing file /opt/airflow/dags/read_dataset_dag.py for tasks to queue
[2024-01-04T21:21:38.589+0000] {logging_mixin.py:188} INFO - [2024-01-04T21:21:38.588+0000] {dagbag.py:538} INFO - Filling up the DagBag from /opt/airflow/dags/read_dataset_dag.py
[2024-01-04T21:21:38.667+0000] {processor.py:840} INFO - DAG(s) 'read_dag_dataset' retrieved from /opt/airflow/dags/read_dataset_dag.py
[2024-01-04T21:21:38.693+0000] {logging_mixin.py:188} INFO - [2024-01-04T21:21:38.693+0000] {dag.py:3033} INFO - Sync 1 DAGs
[2024-01-04T21:21:38.723+0000] {logging_mixin.py:188} INFO - [2024-01-04T21:21:38.723+0000] {dag.py:3820} INFO - Setting next_dagrun for read_dag_dataset to None, run_after=None
[2024-01-04T21:21:38.919+0000] {processor.py:183} INFO - Processing /opt/airflow/dags/read_dataset_dag.py took 0.354 seconds
[2024-01-04T21:22:09.365+0000] {processor.py:161} INFO - Started process (PID=9990) to work on /opt/airflow/dags/read_dataset_dag.py
[2024-01-04T21:22:09.367+0000] {processor.py:830} INFO - Processing file /opt/airflow/dags/read_dataset_dag.py for tasks to queue
[2024-01-04T21:22:09.369+0000] {logging_mixin.py:188} INFO - [2024-01-04T21:22:09.369+0000] {dagbag.py:538} INFO - Filling up the DagBag from /opt/airflow/dags/read_dataset_dag.py
[2024-01-04T21:22:09.441+0000] {processor.py:840} INFO - DAG(s) 'read_dag_dataset' retrieved from /opt/airflow/dags/read_dataset_dag.py
[2024-01-04T21:22:09.516+0000] {logging_mixin.py:188} INFO - [2024-01-04T21:22:09.516+0000] {dag.py:3033} INFO - Sync 1 DAGs
[2024-01-04T21:22:09.617+0000] {logging_mixin.py:188} INFO - [2024-01-04T21:22:09.617+0000] {dag.py:3820} INFO - Setting next_dagrun for read_dag_dataset to None, run_after=None
[2024-01-04T21:22:09.717+0000] {processor.py:183} INFO - Processing /opt/airflow/dags/read_dataset_dag.py took 0.359 seconds
[2024-01-04T21:22:40.520+0000] {processor.py:161} INFO - Started process (PID=10049) to work on /opt/airflow/dags/read_dataset_dag.py
[2024-01-04T21:22:40.526+0000] {processor.py:830} INFO - Processing file /opt/airflow/dags/read_dataset_dag.py for tasks to queue
[2024-01-04T21:22:40.527+0000] {logging_mixin.py:188} INFO - [2024-01-04T21:22:40.527+0000] {dagbag.py:538} INFO - Filling up the DagBag from /opt/airflow/dags/read_dataset_dag.py
[2024-01-04T21:22:40.634+0000] {processor.py:840} INFO - DAG(s) 'read_dag_dataset' retrieved from /opt/airflow/dags/read_dataset_dag.py
[2024-01-04T21:22:40.747+0000] {logging_mixin.py:188} INFO - [2024-01-04T21:22:40.747+0000] {dag.py:3033} INFO - Sync 1 DAGs
[2024-01-04T21:22:40.847+0000] {logging_mixin.py:188} INFO - [2024-01-04T21:22:40.846+0000] {dag.py:3820} INFO - Setting next_dagrun for read_dag_dataset to None, run_after=None
[2024-01-04T21:22:40.916+0000] {processor.py:183} INFO - Processing /opt/airflow/dags/read_dataset_dag.py took 0.430 seconds
[2024-01-04T21:23:11.287+0000] {processor.py:161} INFO - Started process (PID=10108) to work on /opt/airflow/dags/read_dataset_dag.py
[2024-01-04T21:23:11.289+0000] {processor.py:830} INFO - Processing file /opt/airflow/dags/read_dataset_dag.py for tasks to queue
[2024-01-04T21:23:11.290+0000] {logging_mixin.py:188} INFO - [2024-01-04T21:23:11.290+0000] {dagbag.py:538} INFO - Filling up the DagBag from /opt/airflow/dags/read_dataset_dag.py
[2024-01-04T21:23:11.364+0000] {processor.py:840} INFO - DAG(s) 'read_dag_dataset' retrieved from /opt/airflow/dags/read_dataset_dag.py
[2024-01-04T21:23:11.426+0000] {logging_mixin.py:188} INFO - [2024-01-04T21:23:11.425+0000] {dag.py:3033} INFO - Sync 1 DAGs
[2024-01-04T21:23:11.480+0000] {logging_mixin.py:188} INFO - [2024-01-04T21:23:11.479+0000] {dag.py:3820} INFO - Setting next_dagrun for read_dag_dataset to None, run_after=None
[2024-01-04T21:23:11.544+0000] {processor.py:183} INFO - Processing /opt/airflow/dags/read_dataset_dag.py took 0.266 seconds
