[2024-01-04T21:19:05.476+0000] {scheduler_job_runner.py:781} ERROR - Executor reports task instance <TaskInstance: write_dag_dataset.update_file manual__2024-01-04T21:17:43.848318+00:00 [queued]> finished (failed) although the task says it's queued. (Info: None) Was the task killed externally?
